Workbook

Sheet Cornboard Final Data
A1: Pen | B1: Block | C1: Rep | D1: TRT | E1: Initial | F1: HCW | G1: CAFBW | H1: ADG | I1: DMI | J1: G:F | K1: F:G | L1: REA | M1: Yield Grade | N1: Fat | O1: Marbling
A2: 205 | B2: 1 | C2: 1 | D2: 10% MDGS Constant | E2: 572.4 | F2: 776.9 | G2: 1233.1746 | H2: 3.371299 | I2: 21.582642 | J2: 0.15620418 | K2: 6.4018773 | L2: 13.422 | M2: 3.097 | N2: 0.5228 | O2: 533.66667
A3: 206 | B3: 1 | C3: 1 | D3: 10% MDGS Variable | E3: 575.4 | F3: 772.1 | G3: 1232.1429 | H3: 3.359785 | I3: 20.595227 | J3: 0.16313416 | K3: 6.1299241 | L3: 14.018889 | M3: 3.3288889 | N3: 0.57314286 | O3: 485
A4: 207 | B4: 1 | C4: 1 | D4: Control | E4: 579 | F4: 802.2 | G4: 1273.3333 | H4: 3.542517 | I4: 21.495747 | J4: 0.16480083 | K4: 6.0679306 | L4: 13.707 | M4: 3.32 | N4: 0.60466667 | O4: 556.77778
A5: 208 | B5: 1 | C5: 1 | D5: 25% MDGS Variable | E5: 580.5 | F5: 816.5 | G5: 1296.0317 | H5: 3.6506722 | I5: 22.923741 | J5: 0.1592529 | K5: 6.2793205 | L5: 14.25 | M5: 3.35375 | N5: 0.63625 | O5: 547.875
A6: 209 | B6: 1 | C6: 1 | D6: 25% MDGS Constant | E6: 573.55556 | F6: 770.33333 | G6: 1222.7513 | H6: 3.3122233 | I6: 21.321409 | J6: 0.1553473 | K6: 6.4371895 | L6: 13.434444 | M6: 3.4633333 | N6: 0.672 | O6: 486.55556
A7: 210 | B7: 1 | C7: 2 | D7: 10% MDGS Constant | E7: 574.83333 | F7: 773.22222 | G7: 1227.3369 | H7: 3.3290996 | I7: 19.910352 | J7: 0.16720446 | K7: 5.9807017 | L7: 14.002222 | M7: 3.3622222 | N7: 0.64133333 | O7: 521
A8: 211 | B8: 1 | C8: 2 | D8: Control | E8: 575.4 | F8: 752.5 | G8: 1194.4444 | H8: 3.15839 | I8: 19.728558 | J8: 0.16009229 | K8: 6.2463969 | L8: 13.775 | M8: 3.07 | N8: 0.4882 | O8: 515.6
A9: 212 | B9: 1 | C9: 2 | D9: 25% MDGS Variable | E9: 575.6 | F9: 798.5 | G9: 1267.4603 | H9: 3.5298996 | I9: 21.738936 | J9: 0.16237684 | K9: 6.1585139 | L9: 13.28 | M9: 3.328 | N9: 0.577 | O9: 526
A10: 213 | B10: 1 | C10: 2 | D10: 10% MDGS Variable | E10: 571.9 | F10: 851.9 | G10: 1360.8466 | H10: 4.037199 | I10: 22.955779 | J10: 0.17586852 | K10: 5.6860658 | L10: 14.095556 | M10: 3.5933333 | N10: 0.726 | O10: 643.11111
A11: 214 | B11: 1 | C11: 2 | D11: 25% MDGS Constant | E11: 574 | F11: 826.1 | G11: 1311.2698 | H11: 3.7615808 | I11: 22.398785 | J11: 0.16793683 | K11: 5.9546201 | L11: 13.51 | M11: 3.467 | N11: 0.67275 | O11: 539.875
A12: 215 | B12: 2 | C12: 3 | D12: 10% MDGS Variable | E12: 629.55556 | F12: 834.11111 | G12: 1323.9859 | H12: 3.5430119 | I12: 21.579785 | J12: 0.16418198 | K12: 6.0908023 | L12: 14.248571 | M12: 3.2585714 | N12: 0.674 | O12: 548.83333
A13: 216 | B13: 2 | C13: 3 | D13: 10% MDGS Constant | E13: 625.1 | F13: 803.8 | G13: 1275.873 | H13: 3.3202705 | I13: 21.830062 | J13: 0.15209624 | K13: 6.5747843 | L13: 13.67 | M13: 3.425 | N13: 0.6254 | O13: 549.9
... A41: 414 | B41: 3 | C41: 8 | D41: 10% MDGS Variable | E41: 695.2 | F41: 850.7 | G41: 1350.3175 | H41: 3.5995465 | I41: 24.652028 | J41: 0.14601421 | K41: 6.8486483 | L41: 13.082222 | M41: 3.79 | N41: 0.7955 | O41: 630.125

Sheet Performance
A1: Lnk_AnID | B1: 45257 | C1: 45258 | D1: Difference D1-D2 | E1: Average | F1: Block | G1: Strat | H1: Rand | I1: Pen | J1: TRT | K1: Interim | L1: Interim ADG | M1: DMO | N1: G:F | T1: Pen | U1: Block | V1: Rep | W1: Rand | X1: TRT | Y1: Initial | Z1: Interim | AA1: Interim ADG | AB1: DMO | AC1: G:F | AE1: Trt | AF1: Initial | AG1: Interim | AH1: Interim ADG | AI1: DMO | AJ1: G:F | AL1: 205 | AM1: 18.341718
A2: 4437 | B2: =VLOOKUP(A2,'[1]Nebris 11.27'!E:I,5,FALSE) -> 554 | C2: =VLOOKUP(A2,'[1]Nebris 11.28.23'!E:I,5,FALSE) -> 568 | D2: =B2-C2 -> -14 | E2: =AVERAGE(B2:C2) -> 561 | F2: 1 | G2: 1 | H2: 0.13223911 | I2: 205 | J2: =VLOOKUP(I2,$T$2:$X$41,5,FALSE) -> 10% MDGS Constant | K2: =VLOOKUP(A2,'[1]Interim '!E:I,5,FALSE)*0.96 -> 744.96 | L2: =(K2-E2)/58 -> 3.1717241 | M2: =VLOOKUP(I2,$AL$1:$AM$40,2,FALSE) -> 18.341718 | N2: =L2/M2 -> 0.17292405 | T2: 205 | U2: 1 | V2: 1 | W2: 0.44075806 | X2: 10% MDGS Constant | Y2: =AVERAGEIF($I$2:$I$577,T2,$E$2:$E$577) -> 572.4 | Z2: =AVERAGEIF($I$2:$I$577,T2,$K$2:$K$577) -> 744.96 | AA2: =AVERAGEIF($I$2:$I$577,T2,$L$2:$L$577) -> 2.9751724 | AB2: =AVERAGEIF($I$2:$I$577,T2,$M$2:$M$577) -> 18.341718 | AC2: =AVERAGEIF($I$2:$I$577,T2,$N$2:$N$577) -> 0.16220795 | AE2: Control | AF2: =AVERAGEIF($X$2:$X$41,AE2,$Y$2:$Y$41) -> 631.99722 | AG2: =AVERAGEIF($X$2:$X$41,AE2,$Z$2:$Z$41) -> 816.776 | AH2: =AVERAGEIF($X$2:$X$41,AE2,$AA$2:$AA$41) -> 3.185841 | AI2: =AVERAGEIF($X$2:$X$41,AE2,$AB$2:$AB$41) -> 19.157638 | AJ2: =AVERAGEIF($X$2:$X$41,AE2,$AC$2:$AC$41) -> 0.16647684 | AL2: 206 | AM2: 18.076576
A3: 4315 | B3: =VLOOKUP(A3,'[1]Nebris 11.27'!E:I,5,FALSE) -> 554 | C3: =VLOOKUP(A3,'[1]Nebris 11.28.23'!E:I,5,FALSE) -> 554 | D3: =B3-C3 -> 0 | E3: =AVERAGE(B3:C3) -> 554 | F3: 1 | G3: 1 | H3: 0.16749633 | I3: 206 | J3: =VLOOKUP(I3,$T$2:$X$57,5,FALSE) -> 10% MDGS Variable | K3: =VLOOKUP(A3,'[1]Interim '!E:I,5,FALSE)*0.96 -> 714.24 | L3: =(K3-E3)/58 -> 2.7627586 | M3: =VLOOKUP(I3,$AL$1:$AM$40,2,FALSE) -> 18.076576 | N3: =L3/M3 -> 0.15283639 | T3: 206 | U3: 1 | V3: 1 | W3: 0.49100692 | X3: 10% MDGS Variable | Y3: =AVERAGEIF($I$2:$I$577,T3,$E$2:$E$577) -> 575.4 | Z3: =AVERAGEIF($I$2:$I$577,T3,$K$2:$K$577) -> 750.336 | AA3: =AVERAGEIF($I$2:$I$577,T3,$L$2:$L$577) -> 3.0161379 | AB3: =AVERAGEIF($I$2:$I$577,T3,$M$2:$M$577) -> 18.076576 | AC3: =AVERAGEIF($I$2:$I$577,T3,$N$2:$N$577) -> 0.16685339 | AE3: 10% MDGS Constant | AF3: =AVERAGEIF($X$2:$X$41,AE3,$Y$2:$Y$41) -> 632.34514 | AG3: =AVERAGEIF($X$2:$X$41,AE3,$Z$2:$Z$41) -> 820.176 | AH3: =AVERAGEIF($X$2:$X$41,AE3,$AA$2:$AA$41) -> 3.2384631 | AI3: =AVERAGEIF($X$2:$X$41,AE3,$AB$2:$AB$41) -> 19.897121 | AJ3: =AVERAGEIF($X$2:$X$41,AE3,$AC$2:$AC$41) -> 0.16291753 | AL3: 207 | AM3: 18.548331
A4: 4322 | B4: =VLOOKUP(A4,'[1]Nebris 11.27'!E:I,5,FALSE) -> 554 | C4: =VLOOKUP(A4,'[1]Nebris 11.28.23'!E:I,5,FALSE) -> 576 | D4: =B4-C4 -> -22 | E4: =AVERAGE(B4:C4) -> 565 | F4: 1 | G4: 1 | H4: 0.4179676 | I4: 207 | J4: =VLOOKUP(I4,$T$2:$X$57,5,FALSE) -> Control | K4: =VLOOKUP(A4,'[1]Interim '!E:I,5,FALSE)*0.96 -> 756.48 | L4: =(K4-E4)/58 -> 3.3013793 | M4: =VLOOKUP(I4,$AL$1:$AM$40,2,FALSE) -> 18.548331 | N4: =L4/M4 -> 0.17798795 | T4: 207 | U4: 1 | V4: 1 | W4: 0.64886895 | X4: Control | Y4: =AVERAGEIF($I$2:$I$577,T4,$E$2:$E$577) -> 579 | Z4: =AVERAGEIF($I$2:$I$577,T4,$K$2:$K$577) -> 760.704 | AA4: =AVERAGEIF($I$2:$I$577,T4,$L$2:$L$577) -> 3.1328276 | AB4: =AVERAGEIF($I$2:$I$577,T4,$M$2:$M$577) -> 18.548331 | AC4: =AVERAGEIF($I$2:$I$577,T4,$N$2:$N$577) -> 0.16890078 | AE4: 10% MDGS Variable | AF4: =AVERAGEIF($X$2:$X$41,AE4,$Y$2:$Y$41) -> 631.6625 | AG4: =AVERAGEIF($X$2:$X$41,AE4,$Z$2:$Z$41) -> 819 | AH4: =AVERAGEIF($X$2:$X$41,AE4,$AA$2:$AA$41) -> 3.2299569 | AI4: =AVERAGEIF($X$2:$X$41,AE4,$AB$2:$AB$41) -> 20.133268 | AJ4: =AVERAGEIF($X$2:$X$41,AE4,$AC$2:$AC$41) -> 0.16031035 | AL4: 208 | AM4: 20.130157
A5: 4743 | B5: =VLOOKUP(A5,'[1]Nebris 11.27'!E:I,5,FALSE) -> 556 | C5: =VLOOKUP(A5,'[1]Nebris 11.28.23'!E:I,5,FALSE) -> 554 | D5: =B5-C5 -> 2 | E5: =AVERAGE(B5:C5) -> 555 | F5: 1 | G5: 1 | H5: 0.46486563 | I5: 208 | J5: =VLOOKUP(I5,$T$2:$X$57,5,FALSE) -> 25% MDGS Variable | K5: =VLOOKUP(A5,'[1]Interim '!E:I,5,FALSE)*0.96 -> 702.72 | L5: =(K5-E5)/58 -> 2.5468966 | M5: =VLOOKUP(I5,$AL$1:$AM$40,2,FALSE) -> 20.130157 | N5: =L5/M5 -> 0.12652145 | T5: 208 | U5: 1 | V5: 1 | W5: 0.92391597 | X5: 25% MDGS Variable | Y5: =AVERAGEIF($I$2:$I$577,T5,$E$2:$E$577) -> 576.6 | Z5: =AVERAGEIF($I$2:$I$577,T5,$K$2:$K$577) -> 771.264 | AA5: =AVERAGEIF($I$2:$I$577,T5,$L$2:$L$577) -> 3.3562759 | AB5: =AVERAGEIF($I$2:$I$577,T5,$M$2:$M$577) -> 20.130157 | AC5: =AVERAGEIF($I$2:$I$577,T5,$N$2:$N$577) -> 0.16672875 | AE5: 25% MDGS Constant | AF5: =AVERAGEIF($X$2:$X$41,AE5,$Y$2:$Y$41) -> 630.7375 | AG5: =AVERAGEIF($X$2:$X$41,AE5,$Z$2:$Z$41) -> 829.824 | AH5: =AVERAGEIF($X$2:$X$41,AE5,$AA$2:$AA$41) -> 3.4325259 | AI5: =AVERAGEIF($X$2:$X$41,AE5,$AB$2:$AB$41) -> 20.496961 | AJ5: =AVERAGEIF($X$2:$X$41,AE5,$AC$2:$AC$41) -> 0.16731598 | AL5: 209 | AM5: 19.349137
A6: 4765 | B6: =VLOOKUP(A6,'[1]Nebris 11.27'!E:I,5,FALSE) -> 552 | C6: =VLOOKUP(A6,'[1]Nebris 11.28.23'!E:I,5,FALSE) -> 560 | D6: =B6-C6 -> -8 | E6: =AVERAGE(B6:C6) -> 556 | F6: 1 | G6: 1 | H6: 0.49088538 | I6: 209 | J6: =VLOOKUP(I6,$T$2:$X$57,5,FALSE) -> 25% MDGS Constant | K6: =VLOOKUP(A6,'[1]Interim '!E:I,5,FALSE)*0.96 -> 783.36 | L6: =(K6-E6)/58 -> 3.92 | M6: =VLOOKUP(I6,$AL$1:$AM$40,2,FALSE) -> 19.349137 | N6: =L6/M6 -> 0.20259302 | T6: 209 | U6: 1 | V6: 1 | W6: 0.98398342 | X6: 25% MDGS Constant | Y6: =AVERAGEIF($I$2:$I$577,T6,$E$2:$E$577) -> 572 | Z6: =AVERAGEIF($I$2:$I$577,T6,$K$2:$K$577) -> 775.104 | AA6: =AVERAGEIF($I$2:$I$577,T6,$L$2:$L$577) -> 3.5017931 | AB6: =AVERAGEIF($I$2:$I$577,T6,$M$2:$M$577) -> 19.349137 | AC6: =AVERAGEIF($I$2:$I$577,T6,$N$2:$N$577) -> 0.18097929 | AE6: 25% MDGS Variable | AF6: =AVERAGEIF($X$2:$X$41,AE6,$Y$2:$Y$41) -> 632.93194 | AG6: =AVERAGEIF($X$2:$X$41,AE6,$Z$2:$Z$41) -> 817.78667 | AH6: =AVERAGEIF($X$2:$X$41,AE6,$AA$2:$AA$41) -> 3.1965996 | AI6: =AVERAGEIF($X$2:$X$41,AE6,$AB$2:$AB$41) -> 20.163925 | AJ6: =AVERAGEIF($X$2:$X$41,AE6,$AC$2:$AC$41) -> #VALUE! | AL6: 210 | AM6: 17.600604
A7: 4744 | B7: =VLOOKUP(A7,'[1]Nebris 11.27'!E:I,5,FALSE) -> 556 | C7: =VLOOKUP(A7,'[1]Nebris 11.28.23'!E:I,5,FALSE) -> 552 | D7: =B7-C7 -> 4 | E7: =AVERAGE(B7:C7) -> 554 | F7: 1 | G7: 1 | H7: 0.50464714 | I7: 210 | J7: =VLOOKUP(I7,$T$2:$X$57,5,FALSE) -> 10% MDGS Constant | K7: =VLOOKUP(A7,'[1]Interim '!E:I,5,FALSE)*0.96 -> 756.48 | L7: =(K7-E7)/58 -> 3.4910345 | M7: =VLOOKUP(I7,$AL$1:$AM$40,2,FALSE) -> 17.600604 | N7: =L7/M7 -> 0.19834743 | T7: 210 | U7: 1 | V7: 2 | W7: 0.2934528 | X7: 10% MDGS Constant | Y7: =AVERAGEIF($I$2:$I$577,T7,$E$2:$E$577) -> 573.95 | Z7: =AVERAGEIF($I$2:$I$577,T7,$K$2:$K$577) -> 726.72 | AA7: =AVERAGEIF($I$2:$I$577,T7,$L$2:$L$577) -> 2.6339655 | AB7: =AVERAGEIF($I$2:$I$577,T7,$M$2:$M$577) -> 17.600604 | AC7: =AVERAGEIF($I$2:$I$577,T7,$N$2:$N$577) -> 0.149652 | AG7: =AVERAGE(AG2:AG6) -> 820.71253 | AH7: =AVERAGE(AH2:AH6) -> 3.2566773 | AL7: 310 | AM7: 20.764817
A8: 4773 | B8: =VLOOKUP(A8,'[1]Nebris 11.27'!E:I,5,FALSE) -> 554 | C8: =VLOOKUP(A8,'[1]Nebris 11.28.23'!E:I,5,FALSE) -> 578 | D8: =B8-C8 -> -24 | E8: =AVERAGE(B8:C8) -> 566 | F8: 1 | G8: 1 | H8: 0.50851689 | I8: 211 | J8: =VLOOKUP(I8,$T$2:$X$57,5,FALSE) -> Control | K8: =VLOOKUP(A8,'[1]Interim '!E:I,5,FALSE)*0.96 -> 756.48 | L8: =(K8-E8)/58 -> 3.2841379 | M8: =VLOOKUP(I8,$AL$1:$AM$40,2,FALSE) -> 16.604744 | N8: =L8/M8 -> 0.19778311 | T8: 211 | U8: 1 | V8: 2 | W8: 0.44821537 | X8: Control | Y8: =AVERAGEIF($I$2:$I$577,T8,$E$2:$E$577) -> 575.4 | Z8: =AVERAGEIF($I$2:$I$577,T8,$K$2:$K$577) -> 744 | AA8: =AVERAGEIF($I$2:$I$577,T8,$L$2:$L$577) -> 2.9068966 | AB8: =AVERAGEIF($I$2:$I$577,T8,$M$2:$M$577) -> 16.604744 | AC8: =AVERAGEIF($I$2:$I$577,T8,$N$2:$N$577) -> 0.17506422 | AL8: 211 | AM8: 16.604744
A9: 4739 | B9: =VLOOKUP(A9,'[1]Nebris 11.27'!E:I,5,FALSE) -> 556 | C9: =VLOOKUP(A9,'[1]Nebris 11.28.23'!E:I,5,FALSE) -> 554 | D9: =B9-C9 -> 2 | E9: =AVERAGE(B9:C9) -> 555 | F9: 1 | G9: 1 | H9: 0.61147469 | I9: 212 | J9: =VLOOKUP(I9,$T$2:$X$57,5,FALSE) -> 25% MDGS Variable | K9: =VLOOKUP(A9,'[1]Interim '!E:I,5,FALSE)*0.96 -> 768 | L9: =(K9-E9)/58 -> 3.6724138 | M9: =VLOOKUP(I9,$AL$1:$AM$40,2,FALSE) -> 19.734967 | N9: =L9/M9 -> 0.18608664 | T9: 212 | U9: 1 | V9: 2 | W9: 0.88326655 | X9: 25% MDGS Variable | Y9: =AVERAGEIF($I$2:$I$577,T9,$E$2:$E$577) -> 575.6 | Z9: =AVERAGEIF($I$2:$I$577,T9,$K$2:$K$577) -> 777.6 | AA9: =AVERAGEIF($I$2:$I$577,T9,$L$2:$L$577) -> 3.4827586 | AB9: =AVERAGEIF($I$2:$I$577,T9,$M$2:$M$577) -> 19.734967 | AC9: =AVERAGEIF($I$2:$I$577,T9,$N$2:$N$577) -> 0.17647653 | AE9: Projections | AF9: 45316 | AL9: 212 | AM9: 19.734967
A10: 4485 | B10: =VLOOKUP(A10,'[1]Nebris 11.27'!E:I,5,FALSE) -> 556 | C10: =VLOOKUP(A10,'[1]Nebris 11.28.23'!E:I,5,FALSE) -> 558 | D10: =B10-C10 -> -2 | E10: =AVERAGE(B10:C10) -> 557 | F10: 1 | G10: 1 | H10: 0.7250652 | I10: 213 | J10: =VLOOKUP(I10,$T$2:$X$57,5,FALSE) -> 10% MDGS Variable | K10: =VLOOKUP(A10,'[1]Interim '!E:I,5,FALSE)*0.96 -> 819.84 | L10: =(K10-E10)/58 -> 4.5317241 | M10: =VLOOKUP(I10,$AL$1:$AM$40,2,FALSE) -> 19.380345 | N10: =L10/M10 -> 0.23383093 | T10: 213 | U10: 1 | V10: 2 | W10: 0.89946529 | X10: 10% MDGS Variable | Y10: =AVERAGEIF($I$2:$I$577,T10,$E$2:$E$577) -> 571.9 | Z10: =AVERAGEIF($I$2:$I$577,T10,$K$2:$K$577) -> 784.704 | AA10: =AVERAGEIF($I$2:$I$577,T10,$L$2:$L$577) -> 3.6690345 | AB10: =AVERAGEIF($I$2:$I$577,T10,$M$2:$M$577) -> 19.380345 | AC10: =AVERAGEIF($I$2:$I$577,T10,$N$2:$N$577) -> 0.18931729 | AE10: =1350-AG7 -> 529.28747 | AF10: =AE10/AH7 -> 162.52377 | AL10: 213 | AM10: 19.380345
A11: 4603 | B11: =VLOOKUP(A11,'[1]Nebris 11.27'!E:I,5,FALSE) -> 554 | C11: =VLOOKUP(A11,'[1]Nebris 11.28.23'!E:I,5,FALSE) -> 570 | D11: =B11-C11 -> -16 | E11: =AVERAGE(B11:C11) -> 562 | F11: 1 | G11: 1 | H11: 0.74773755 | I11: 214 | J11: =VLOOKUP(I11,$T$2:$X$57,5,FALSE) -> 25% MDGS Constant | K11: =VLOOKUP(A11,'[1]Interim '!E:I,5,FALSE)*0.96 -> 748.8 | L11: =(K11-E11)/58 -> 3.2206897 | M11: =VLOOKUP(I11,$AL$1:$AM$40,2,FALSE) -> 19.209834 | N11: =L11/M11 -> 0.16765838 | T11: 214 | U11: 1 | V11: 2 | W11: 0.9803855 | X11: 25% MDGS Constant | Y11: =AVERAGEIF($I$2:$I$577,T11,$E$2:$E$577) -> 574 | Z11: =AVERAGEIF($I$2:$I$577,T11,$K$2:$K$577) -> 767.808 | AA11: =AVERAGEIF($I$2:$I$577,T11,$L$2:$L$577) -> 3.3415172 | AB11: =AVERAGEIF($I$2:$I$577,T11,$M$2:$M$577) -> 19.209834 | AC11: =AVERAGEIF($I$2:$I$577,T11,$N$2:$N$577) -> 0.17394826 | AE11: =1400-AG7 -> 579.28747 | AF11: =AE11/AH7 -> 177.87684 | AL11: 214 | AM11: 19.209834
A12: 4683 | B12: =VLOOKUP(A12,'[1]Nebris 11.27'!E:I,5,FALSE) -> 558 | C12: =VLOOKUP(A12,'[1]Nebris 11.28.23'!E:I,5,FALSE) -> 550 | D12: =B12-C12 -> 8 | E12: =AVERAGE(B12:C12) -> 554 | F12: 1 | G12: 2 | H12: 0.073321961 | I12: 205 | J12: =VLOOKUP(I12,$T$2:$X$57,5,FALSE) -> 10% MDGS Constant | K12: =VLOOKUP(A12,'[1]Interim '!E:I,5,FALSE)*0.96 -> 700.8 | L12: =(K12-E12)/58 -> 2.5310345 | M12: =VLOOKUP(I12,$AL$1:$AM$40,2,FALSE) -> 18.341718 | N12: =L12/M12 -> 0.13799331 | T12: 215 | U12: 2 | V12: 3 | W12: 0.27775314 | X12: 10% MDGS Variable | Y12: =AVERAGEIF($I$2:$I$577,T12,$E$2:$E$577) -> 629.6 | Z12: =AVERAGEIF($I$2:$I$577,T12,$K$2:$K$577) -> 793.152 | AA12: =AVERAGEIF($I$2:$I$577,T12,$L$2:$L$577) -> 2.8198621 | AB12: =AVERAGEIF($I$2:$I$577,T12,$M$2:$M$577) -> 19.107699 | AC12: =AVERAGEIF($I$2:$I$577,T12,$N$2:$N$577) -> 0.14757727 | AE12: =1450-AG7 -> 629.28747 | AF12: =AE12/AH7 -> 193.22991 | AL12: 215 | AM12: 19.107699
A13: 4313 | B13: =VLOOKUP(A13,'[1]Nebris 11.27'!E:I,5,FALSE) -> 560 | C13: =VLOOKUP(A13,'[1]Nebris 11.28.23'!E:I,5,FALSE) -> 560 | D13: =B13-C13 -> 0 | E13: =AVERAGE(B13:C13) -> 560 | F13: 1 | G13: 2 | H13: 0.080928873 | I13: 206 | J13: =VLOOKUP(I13,$T$2:$X$57,5,FALSE) -> 10% MDGS Variable | K13: =VLOOKUP(A13,'[1]Interim '!E:I,5,FALSE)*0.96 -> 721.92 | L13: =(K13-E13)/58 -> 2.7917241 | M13: =VLOOKUP(I13,$AL$1:$AM$40,2,FALSE) -> 18.076576 | N13: =L13/M13 -> 0.15443877 | T13: 216 | U13: 2 | V13: 3 | W13: 0.51430711 | X13: 10% MDGS Constant | Y13: =AVERAGEIF($I$2:$I$577,T13,$E$2:$E$577) -> 625.1 | Z13: =AVERAGEIF($I$2:$I$577,T13,$K$2:$K$577) -> 813.504 | AA13: =AVERAGEIF($I$2:$I$577,T13,$L$2:$L$577) -> 3.2483448 | AB13: =AVERAGEIF($I$2:$I$577,T13,$M$2:$M$577) -> 20.39879 | AC13: =AVERAGEIF($I$2:$I$577,T13,$N$2:$N$577) -> 0.15924204 | AE13: =1500-AG7 -> 679.28747 | AF13: =AE13/AH7 -> 208.58298 | AL13: 216 | AM13: 20.39879
A14: 4418 | B14: =VLOOKUP(A14,'[1]Nebris 11.27'!E:I,5,FALSE) -> 558 | C14: =VLOOKUP(A14,'[1]Nebris 11.28.23'!E:I,5,FALSE) -> 586 | D14: =B14-C14 -> -28 | E14: =AVERAGE(B14:C14) -> 572 | F14: 1 | G14: 2 | H14: 0.086370454 | I14: 207 | J14: =VLOOKUP(I14,$T$2:$X$57,5,FALSE) -> Control | K14: =VLOOKUP(A14,'[1]Interim '!E:I,5,FALSE)*0.96 -> 741.12 | L14: =(K14-E14)/58 -> 2.9158621 | M14: =VLOOKUP(I14,$AL$1:$AM$40,2,FALSE) -> 18.548331 | N14: =L14/M14 -> 0.15720348 | T14: 301 | U14: 2 | V14: 3 | W14: 0.82991235 | X14: 25% MDGS Constant | Y14: =AVERAGEIF($I$2:$I$577,T14,$E$2:$E$577) -> 627.9 | Z14: =AVERAGEIF($I$2:$I$577,T14,$K$2:$K$577) -> 811.008 | AA14: =AVERAGEIF($I$2:$I$577,T14,$L$2:$L$577) -> 3.1570345 | AB14: =AVERAGEIF($I$2:$I$577,T14,$M$2:$M$577) -> 19.764341 | AC14: =AVERAGEIF($I$2:$I$577,T14,$N$2:$N$577) -> 0.15973386 | AL14: 301 | AM14: 19.764341
A15: 4376 | B15: =VLOOKUP(A15,'[1]Nebris 11.27'!E:I,5,FALSE) -> 560 | C15: =VLOOKUP(A15,'[1]Nebris 11.28.23'!E:I,5,FALSE) -> 580 | D15: =B15-C15 -> -20 | E15: =AVERAGE(B15:C15) -> 570 | F15: 1 | G15: 2 | H15: 0.51308819 | I15: 208 | J15: =VLOOKUP(I15,$T$2:$X$57,5,FALSE) -> 25% MDGS Variable | K15: =VLOOKUP(A15,'[1]Interim '!E:I,5,FALSE)*0.96 -> 775.68 | L15: =(K15-E15)/58 -> 3.5462069 | M15: =VLOOKUP(I15,$AL$1:$AM$40,2,FALSE) -> 20.130157 | N15: =L15/M15 -> 0.1761639 | T15: 302 | U15: 2 | V15: 3 | W15: 0.973114 | X15: 25% MDGS Variable | Y15: =AVERAGEIF($I$2:$I$577,T15,$E$2:$E$577) -> 628.55556 | Z15: =AVERAGEIF($I$2:$I$577,T15,$K$2:$K$577) -> 784.21333 | AA15: =AVERAGEIF($I$2:$I$577,T15,$L$2:$L$577) -> 2.6837548 | AB15: =AVERAGEIF($I$2:$I$577,T15,$M$2:$M$577) -> 18.146164 | AC15: =AVERAGEIF($I$2:$I$577,T15,$N$2:$N$577) -> 0.14789654 | AE15: 3.3 | AF15: 1300 | AG15: 1350 | AH15: 1400 | AI15: 1450 | AL15: 302 | AM15: 18.146164
A16: 4605 | B16: =VLOOKUP(A16,'[1]Nebris 11.27'!E:I,5,FALSE) -> 558 | C16: =VLOOKUP(A16,'[1]Nebris 11.28.23'!E:I,5,FALSE) -> 558 | D16: =B16-C16 -> 0 | E16: =AVERAGE(B16:C16) -> 558 | F16: 1 | G16: 2 | H16: 0.54242732 | I16: 209 | J16: =VLOOKUP(I16,$T$2:$X$57,5,FALSE) -> 25% MDGS Constant | K16: =VLOOKUP(A16,'[1]Interim '!E:I,5,FALSE)*0.96 -> 746.88 | L16: =(K16-E16)/58 -> 3.2565517 | M16: =VLOOKUP(I16,$AL$1:$AM$40,2,FALSE) -> 19.349137 | N16: =L16/M16 -> 0.16830475 | T16: 303 | U16: 2 | V16: 3 | W16: 0.97591178 | X16: Control | Y16: =AVERAGEIF($I$2:$I$577,T16,$E$2:$E$577) -> 627.3 | Z16: =AVERAGEIF($I$2:$I$577,T16,$K$2:$K$577) -> 793.344 | AA16: =AVERAGEIF($I$2:$I$577,T16,$L$2:$L$577) -> 2.8628276 | AB16: =AVERAGEIF($I$2:$I$577,T16,$M$2:$M$577) -> 18.06332 | AC16: =AVERAGEIF($I$2:$I$577,T16,$N$2:$N$577) -> 0.15848845 | AD16: Light | AE16: 760 | AF16: =AF15-AE16 -> 540 | AG16: =1350-AE16 -> 590 | AH16: =1400-AE16 -> 640 | AI16: =1450-AE16 -> 690 | AL16: 303 | AM16: 18.06332
A17: 4337 | B17: =VLOOKUP(A17,'[1]Nebris 11.27'!E:I,5,FALSE) -> 558 | C17: =VLOOKUP(A17,'[1]Nebris 11.28.23'!E:I,5,FALSE) -> 574 | D17: =B17-C17 -> -16 | E17: =AVERAGE(B17:C17) -> 566 | F17: 1 | G17: 2 | H17: 0.62471381 | I17: 210 | J17: =VLOOKUP(I17,$T$2:$X$57,5,FALSE) -> 10% MDGS Constant | K17: =VLOOKUP(A17,'[1]Interim '!E:I,5,FALSE)*0.96 -> 696.96 | L17: =(K17-E17)/58 -> 2.257931 | M17: =VLOOKUP(I17,$AL$1:$AM$40,2,FALSE) -> 17.600604 | N17: =L17/M17 -> 0.12828713 | T17: 304 | U17: 2 | V17: 4 | W17: 0.01344788 | X17: 10% MDGS Variable | Y17: =AVERAGEIF($I$2:$I$577,T17,$E$2:$E$577) -> 628.1 | Z17: =AVERAGEIF($I$2:$I$577,T17,$K$2:$K$577) -> 772.032 | AA17: =AVERAGEIF($I$2:$I$577,T17,$L$2:$L$577) -> 2.4815862 | AB17: =AVERAGEIF($I$2:$I$577,T17,$M$2:$M$577) -> 18.555516 | AC17: =AVERAGEIF($I$2:$I$577,T17,$N$2:$N$577) -> 0.13373847 | AD17: Mid | AE17: 812 | AF17: =AF15-AE17 -> 488 | AG17: =1350-AE17 -> 538 | AH17: =1400-AE17 -> 588 | AI17: =1450-AE17 -> 638 | AL17: 304 | AM17: 18.555516
A18: 4365 | B18: =VLOOKUP(A18,'[1]Nebris 11.27'!E:I,5,FALSE) -> 558 | C18: =VLOOKUP(A18,'[1]Nebris 11.28.23'!E:I,5,FALSE) -> 574 | D18: =B18-C18 -> -16 | E18: =AVERAGE(B18:C18) -> 566 | F18: 1 | G18: 2 | H18: 0.71135622 | I18: 211 | J18: =VLOOKUP(I18,$T$2:$X$57,5,FALSE) -> Control | K18: =VLOOKUP(A18,'[1]Interim '!E:I,5,FALSE)*0.96 -> 746.88 | L18: =(K18-E18)/58 -> 3.1186207 | M18: =VLOOKUP(I18,$AL$1:$AM$40,2,FALSE) -> 16.604744 | N18: =L18/M18 -> 0.18781504 | T18: 305 | U18: 2 | V18: 4 | W18: 0.43508579 | X18: 10% MDGS Constant | Y18: =AVERAGEIF($I$2:$I$577,T18,$E$2:$E$577) -> 626.3 | Z18: =AVERAGEIF($I$2:$I$577,T18,$K$2:$K$577) -> 804.48 | AA18: =AVERAGEIF($I$2:$I$577,T18,$L$2:$L$577) -> 3.072069 | AB18: =AVERAGEIF($I$2:$I$577,T18,$M$2:$M$577) -> 18.368633 | AC18: =AVERAGEIF($I$2:$I$577,T18,$N$2:$N$577) -> 0.16724538 | AD18: Heavy | AE18: 899 | AF18: =AF15-AE18 -> 401 | AG18: =1350-AE18 -> 451 | AH18: =1400-AE18 -> 501 | AI18: =1450-AE18 -> 551 | AL18: 305 | AM18: 18.368633
A19: 4502 | B19: =VLOOKUP(A19,'[1]Nebris 11.27'!E:I,5,FALSE) -> 558 | C19: =VLOOKUP(A19,'[1]Nebris 11.28.23'!E:I,5,FALSE) -> 570 | D19: =B19-C19 -> -12 | E19: =AVERAGE(B19:C19) -> 564 | F19: 1 | G19: 2 | H19: 0.83731892 | I19: 212 | J19: =VLOOKUP(I19,$T$2:$X$57,5,FALSE) -> 25% MDGS Variable | K19: =VLOOKUP(A19,'[1]Interim '!E:I,5,FALSE)*0.96 -> 779.52 | L19: =(K19-E19)/58 -> 3.7158621 | M19: =VLOOKUP(I19,$AL$1:$AM$40,2,FALSE) -> 19.734967 | N19: =L19/M19 -> 0.18828823 | T19: 306 | U19: 2 | V19: 4 | W19: 0.48109753 | X19: Control | Y19: =AVERAGEIF($I$2:$I$577,T19,$E$2:$E$577) -> 625.66667 | Z19: =AVERAGEIF($I$2:$I$577,T19,$K$2:$K$577) -> 802.56 | AA19: =AVERAGEIF($I$2:$I$577,T19,$L$2:$L$577) -> 3.0498851 | AB19: =AVERAGEIF($I$2:$I$577,T19,$M$2:$M$577) -> 19.337783 | AC19: =AVERAGEIF($I$2:$I$577,T19,$N$2:$N$577) -> 0.15771637 | AL19: 306 | AM19: 19.337783
A20: 4755 | B20: =VLOOKUP(A20,'[1]Nebris 11.27'!E:I,5,FALSE) -> 558 | C20: =VLOOKUP(A20,'[1]Nebris 11.28.23'!E:I,5,FALSE) -> 544 | D20: =B20-C20 -> 14 | E20: =AVERAGE(B20:C20) -> 551 | F20: 1 | G20: 2 | H20: 0.86435 | I20: 213 | J20: =VLOOKUP(I20,$T$2:$X$57,5,FALSE) -> 10% MDGS Variable | K20: =VLOOKUP(A20,'[1]Interim '!E:I,5,FALSE)*0.96 -> 762.24 | L20: =(K20-E20)/58 -> 3.642069 | M20: =VLOOKUP(I20,$AL$1:$AM$40,2,FALSE) -> 19.380345 | N20: =L20/M20 -> 0.18792591 | T20: 307 | U20: 2 | V20: 4 | W20: 0.54707952 | X20: 25% MDGS Variable | Y20: =AVERAGEIF($I$2:$I$577,T20,$E$2:$E$577) -> 624.7 | Z20: =AVERAGEIF($I$2:$I$577,T20,$K$2:$K$577) -> 802.176 | AA20: =AVERAGEIF($I$2:$I$577,T20,$L$2:$L$577) -> 3.059931 | AB20: =AVERAGEIF($I$2:$I$577,T20,$M$2:$M$577) -> 19.036106 | AC20: =AVERAGEIF($I$2:$I$577,T20,$N$2:$N$577) -> 0.16074354 | AE20: Light | AF20: =AF16/AE15 -> 163.63636 | AG20: =AG16/AE15 -> 178.78788 | AH20: =AH16/AE15 -> 193.93939 | AI20: =AI16/AE15 -> 209.09091 | AL20: 307 | AM20: 19.036106
A21: 4460 | B21: =VLOOKUP(A21,'[1]Nebris 11.27'!E:I,5,FALSE) -> 560 | C21: =VLOOKUP(A21,'[1]Nebris 11.28.23'!E:I,5,FALSE) -> 552 | D21: =B21-C21 -> 8 | E21: =AVERAGE(B21:C21) -> 556 | F21: 1 | G21: 2 | H21: 0.91464544 | I21: 214 | J21: =VLOOKUP(I21,$T$2:$X$57,5,FALSE) -> 25% MDGS Constant | K21: =VLOOKUP(A21,'[1]Interim '!E:I,5,FALSE)*0.96 -> 771.84 | L21: =(K21-E21)/58 -> 3.7213793 | M21: =VLOOKUP(I21,$AL$1:$AM$40,2,FALSE) -> 19.209834 | N21: =L21/M21 -> 0.19372261 | T21: 308 | U21: 2 | V21: 4 | W21: 0.88115405 | X21: 25% MDGS Constant | Y21: =AVERAGEIF($I$2:$I$577,T21,$E$2:$E$577) -> 626.7 | Z21: =AVERAGEIF($I$2:$I$577,T21,$K$2:$K$577) -> 804.48 | AA21: =AVERAGEIF($I$2:$I$577,T21,$L$2:$L$577) -> 3.0651724 | AB21: =AVERAGEIF($I$2:$I$577,T21,$M$2:$M$577) -> 19.826311 | AC21: =AVERAGEIF($I$2:$I$577,T21,$N$2:$N$577) -> 0.15460124 | AE21: Mid | AF21: =AF17/AE15 -> 147.87879 | AG21: =AG17/AE15 -> 163.0303 | AH21: =AH17/AE15 -> 178.18182 | AI21: =AI17/AE15 -> 193.33333 | AL21: 308 | AM21: 19.826311
A22: 4317 | B22: =VLOOKUP(A22,'[1]Nebris 11.27'!E:I,5,FALSE) -> 562 | C22: =VLOOKUP(A22,'[1]Nebris 11.28.23'!E:I,5,FALSE) -> 564 | D22: =B22-C22 -> -2 | E22: =AVERAGE(B22:C22) -> 563 | F22: 1 | G22: 3 | H22: 0.11651434 | I22: 205 | J22: =VLOOKUP(I22,$T$2:$X$57,5,FALSE) -> 10% MDGS Constant | K22: =VLOOKUP(A22,'[1]Interim '!E:I,5,FALSE)*0.96 -> 735.36 | L22: =(K22-E22)/58 -> 2.9717241 | M22: =VLOOKUP(I22,$AL$1:$AM$40,2,FALSE) -> 18.341718 | N22: =L22/M22 -> 0.16201994 | T22: 309 | U22: 2 | V22: 5 | W22: 0.059719457 | X22: Control | Y22: =AVERAGEIF($I$2:$I$577,T22,$E$2:$E$577) -> 626.7 | Z22: =AVERAGEIF($I$2:$I$577,T22,$K$2:$K$577) -> 842.88 | AA22: =AVERAGEIF($I$2:$I$577,T22,$L$2:$L$577) -> 3.7272414 | AB22: =AVERAGEIF($I$2:$I$577,T22,$M$2:$M$577) -> 19.729599 | AC22: =AVERAGEIF($I$2:$I$577,T22,$N$2:$N$577) -> 0.18891623 | AE22: Heavy | AF22: =AF18/AE15 -> 121.51515 | AG22: =AG18/AE15 -> 136.66667 | AH22: =AH18/AE15 -> 151.81818 | AI22: =AI18/AE15 -> 166.9697 | AL22: 309 | AM22: 19.729599
A23: 4333 | B23: =VLOOKUP(A23,'[1]Nebris 11.27'!E:I,5,FALSE) -> 564 | C23: =VLOOKUP(A23,'[1]Nebris 11.28.23'!E:I,5,FALSE) -> 570 | D23: =B23-C23 -> -6 | E23: =AVERAGE(B23:C23) -> 567 | F23: 1 | G23: 3 | H23: 0.13354625 | I23: 206 | J23: =VLOOKUP(I23,$T$2:$X$57,5,FALSE) -> 10% MDGS Variable | K23: =VLOOKUP(A23,'[1]Interim '!E:I,5,FALSE)*0.96 -> 689.28 | L23: =(K23-E23)/58 -> 2.1082759 | M23: =VLOOKUP(I23,$AL$1:$AM$40,2,FALSE) -> 18.076576 | N23: =L23/M23 -> 0.11663027 | T23: 310 | U23: 2 | V23: 5 | W23: 0.07244734 | X23: 10% MDGS Variable | Y23: =AVERAGEIF($I$2:$I$577,T23,$E$2:$E$577) -> 629 | Z23: =AVERAGEIF($I$2:$I$577,T23,$K$2:$K$577) -> 831.744 | AA23: =AVERAGEIF($I$2:$I$577,T23,$L$2:$L$577) -> 3.4955862 | AB23: =AVERAGEIF($I$2:$I$577,T23,$M$2:$M$577) -> 20.764817 | AC23: =AVERAGEIF($I$2:$I$577,T23,$N$2:$N$577) -> 0.16834178 | AL23: 311 | AM23: 21.070005
A24: 4700 | B24: =VLOOKUP(A24,'[1]Nebris 11.27'!E:I,5,FALSE) -> 564 | C24: =VLOOKUP(A24,'[1]Nebris 11.28.23'!E:I,5,FALSE) -> 570 | D24: =B24-C24 -> -6 | E24: =AVERAGE(B24:C24) -> 567 | F24: 1 | G24: 3 | H24: 0.13431988 | I24: 207 | J24: =VLOOKUP(I24,$T$2:$X$57,5,FALSE) -> Control | K24: =VLOOKUP(A24,'[1]Interim '!E:I,5,FALSE)*0.96 -> 768 | L24: =(K24-E24)/58 -> 3.4655172 | M24: =VLOOKUP(I24,$AL$1:$AM$40,2,FALSE) -> 18.548331 | N24: =L24/M24 -> 0.18683715 | T24: 311 | U24: 2 | V24: 5 | W24: 0.6685766 | X24: 10% MDGS Constant | Y24: =AVERAGEIF($I$2:$I$577,T24,$E$2:$E$577) -> 631.3 | Z24: =AVERAGEIF($I$2:$I$577,T24,$K$2:$K$577) -> 822.144 | AA24: =AVERAGEIF($I$2:$I$577,T24,$L$2:$L$577) -> 3.2904138 | AB24: =AVERAGEIF($I$2:$I$577,T24,$M$2:$M$577) -> 21.070005 | AC24: =AVERAGEIF($I$2:$I$577,T24,$N$2:$N$577) -> 0.15889378 | AE24: Light | AF24: =DATE(2024,1,25)+AF20 -> 45479.636 | AG24: =DATE(2024,1,25)+AG20 -> 45494.788 | AH24: =DATE(2024,1,25)+AH20 -> 45509.939 | AI24: =DATE(2024,1,25)+AI20 -> 45525.091 | AL24: 312 | AM24: 20.72641
A25: 4445 | B25: =VLOOKUP(A25,'[1]Nebris 11.27'!E:I,5,FALSE) -> 562 | C25: =VLOOKUP(A25,'[1]Nebris 11.28.23'!E:I,5,FALSE) -> 572 | D25: =B25-C25 -> -10 | E25: =AVERAGE(B25:C25) -> 567 | F25: 1 | G25: 3 | H25: 0.25443115 | I25: 208 | J25: =VLOOKUP(I25,$T$2:$X$57,5,FALSE) -> 25% MDGS Variable | K25: =VLOOKUP(A25,'[1]Interim '!E:I,5,FALSE)*0.96 -> 769.92 | L25: =(K25-E25)/58 -> 3.4986207 | M25: =VLOOKUP(I25,$AL$1:$AM$40,2,FALSE) -> 20.130157 | N25: =L25/M25 -> 0.17379997 | T25: 312 | U25: 2 | V25: 5 | W25: 0.89781507 | X25: 25% MDGS Constant | Y25: =AVERAGEIF($I$2:$I$577,T25,$E$2:$E$577) -> 629.1 | Z25: =AVERAGEIF($I$2:$I$577,T25,$K$2:$K$577) -> 806.784 | AA25: =AVERAGEIF($I$2:$I$577,T25,$L$2:$L$577) -> 3.0635172 | AB25: =AVERAGEIF($I$2:$I$577,T25,$M$2:$M$577) -> 20.72641 | AC25: =AVERAGEIF($I$2:$I$577,T25,$N$2:$N$577) -> 0.14780742 | AE25: Mid | AF25: =DATE(2024,1,25)+AF21 -> 45463.879 | AG25: =DATE(2024,1,25)+AG21 -> 45479.03 | AH25: =DATE(2024,1,25)+AH21 -> 45494.182 | AI25: =DATE(2024,1,25)+AI21 -> 45509.333 | AL25: 313 | AM25: 20.372525
A26: 4357 | B26: =VLOOKUP(A26,'[1]Nebris 11.27'!E:I,5,FALSE) -> 562 | C26: =VLOOKUP(A26,'[1]Nebris 11.28.23'!E:I,5,FALSE) -> 556 | D26: =B26-C26 -> 6 | E26: =AVERAGE(B26:C26) -> 559 | F26: 1 | G26: 3 | H26: 0.27863879 | I26: 209 | J26: =VLOOKUP(I26,$T$2:$X$57,5,FALSE) -> 25% MDGS Constant | K26: =VLOOKUP(A26,'[1]Interim '!E:I,5,FALSE)*0.96 -> 775.68 | L26: =(K26-E26)/58 -> 3.7358621 | M26: =VLOOKUP(I26,$AL$1:$AM$40,2,FALSE) -> 19.349137 | N26: =L26/M26 -> 0.19307642 | T26: 313 | U26: 2 | V26: 5 | W26: 0.98450075 | X26: 25% MDGS Variable | Y26: =AVERAGEIF($I$2:$I$577,T26,$E$2:$E$577) -> 627.3 | Z26: =AVERAGEIF($I$2:$I$577,T26,$K$2:$K$577) -> 817.92 | AA26: =AVERAGEIF($I$2:$I$577,T26,$L$2:$L$577) -> 3.3621456 | AB26: =AVERAGEIF($I$2:$I$577,T26,$M$2:$M$577) -> 20.372525 | AC26: =AVERAGEIF($I$2:$I$577,T26,$N$2:$N$577) -> #VALUE! | AE26: Heavy | AF26: =DATE(2024,1,25)+AF22 -> 45437.515 | AG26: =DATE(2024,1,25)+AG22 -> 45452.667 | AH26: =DATE(2024,1,25)+AH22 -> 45467.818 | AI26: =DATE(2024,1,25)+AI22 -> 45482.97 | AL26: 314 | AM26: 21.540377
A27: 4691 | B27: =VLOOKUP(A27,'[1]Nebris 11.27'!E:I,5,FALSE) -> 560 | C27: =VLOOKUP(A27,'[1]Nebris 11.28.23'!E:I,5,FALSE) -> 574 | D27: =B27-C27 -> -14 | E27: =AVERAGE(B27:C27) -> 567 | F27: 1 | G27: 3 | H27: 0.34361157 | I27: 210 | J27: =VLOOKUP(I27,$T$2:$X$57,5,FALSE) -> 10% MDGS Constant | K27: =VLOOKUP(A27,'[1]Interim '!E:I,5,FALSE)*0.96 -> 714.24 | L27: =(K27-E27)/58 -> 2.5386207 | M27: =VLOOKUP(I27,$AL$1:$AM$40,2,FALSE) -> 17.600604 | N27: =L27/M27 -> 0.14423486 | T27: 314 | U27: 2 | V27: 6 | W27: 0.36164609 | X27: 25% MDGS Variable | Y27: =AVERAGEIF($I$2:$I$577,T27,$E$2:$E$577) -> 631.1 | Z27: =AVERAGEIF($I$2:$I$577,T27,$K$2:$K$577) -> 840.192 | AA27: =AVERAGEIF($I$2:$I$577,T27,$L$2:$L$577) -> 3.6050345 | AB27: =AVERAGEIF($I$2:$I$577,T27,$M$2:$M$577) -> 21.540377 | AC27: =AVERAGEIF($I$2:$I$577,T27,$N$2:$N$577) -> 0.16736172 | AL27: 315 | AM27: 20.610382
A28: 4423 | B28: =VLOOKUP(A28,'[1]Nebris 11.27'!E:I,5,FALSE) -> 564 | C28: =VLOOKUP(A28,'[1]Nebris 11.28.23'!E:I,5,FALSE) -> 580 | D28: =B28-C28 -> -16 | E28: =AVERAGE(B28:C28) -> 572 | F28: 1 | G28: 3 | H28: 0.54959193 | I28: 211 | J28: =VLOOKUP(I28,$T$2:$X$57,5,FALSE) -> Control | K28: =VLOOKUP(A28,'[1]Interim '!E:I,5,FALSE)*0.96 -> 723.84 | L28: =(K28-E28)/58 -> 2.617931 | M28: =VLOOKUP(I28,$AL$1:$AM$40,2,FALSE) -> 16.604744 | N28: =L28/M28 -> 0.15766163 | T28: 315 | U28: 2 | V28: 6 | W28: 0.52656808 | X28: 25% MDGS Constant | Y28: =AVERAGEIF($I$2:$I$577,T28,$E$2:$E$577) -> 622.9 | Z28: =AVERAGEIF($I$2:$I$577,T28,$K$2:$K$577) -> 820.992 | AA28: =AVERAGEIF($I$2:$I$577,T28,$L$2:$L$577) -> 3.4153793 | AB28: =AVERAGEIF($I$2:$I$577,T28,$M$2:$M$577) -> 20.610382 | AC28: =AVERAGEIF($I$2:$I$577,T28,$N$2:$N$577) -> 0.1657116 | AL28: 316 | AM28: 20.102195
A29: 4702 | B29: =VLOOKUP(A29,'[1]Nebris 11.27'!E:I,5,FALSE) -> 560 | C29: =VLOOKUP(A29,'[1]Nebris 11.28.23'!E:I,5,FALSE) -> 572 | D29: =B29-C29 -> -12 | E29: =AVERAGE(B29:C29) -> 566 | F29: 1 | G29: 3 | H29: 0.61999853 | I29: 212 | J29: =VLOOKUP(I29,$T$2:$X$57,5,FALSE) -> 25% MDGS Variable | K29: =VLOOKUP(A29,'[1]Interim '!E:I,5,FALSE)*0.96 -> 762.24 | L29: =(K29-E29)/58 -> 3.3834483 | M29: =VLOOKUP(I29,$AL$1:$AM$40,2,FALSE) -> 19.734967 | N29: =L29/M29 -> 0.17144433 | T29: 316 | U29: 2 | V29: 6 | W29: 0.58168133 | X29: 10% MDGS Constant | Y29: =AVERAGEIF($I$2:$I$577,T29,$E$2:$E$577) -> 626.9 | Z29: =AVERAGEIF($I$2:$I$577,T29,$K$2:$K$577) -> 838.464 | AA29: =AVERAGEIF($I$2:$I$577,T29,$L$2:$L$577) -> 3.6476552 | AB29: =AVERAGEIF($I$2:$I$577,T29,$M$2:$M$577) -> 20.102195 | AC29: =AVERAGEIF($I$2:$I$577,T29,$N$2:$N$577) -> 0.18145556 | AL29: 317 | AM29: 19.655293
A30: 4328 | B30: =VLOOKUP(A30,'[1]Nebris 11.27'!E:I,5,FALSE) -> 564 | C30: =VLOOKUP(A30,'[1]Nebris 11.28.23'!E:I,5,FALSE) -> 556 | D30: =B30-C30 -> 8 | E30: =AVERAGE(B30:C30) -> 560 | F30: 1 | G30: 3 | H30: 0.6575979 | I30: 213 | J30: =VLOOKUP(I30,$T$2:$X$57,5,FALSE) -> 10% MDGS Variable | K30: =VLOOKUP(A30,'[1]Interim '!E:I,5,FALSE)*0.96 -> 756.48 | L30: =(K30-E30)/58 -> 3.3875862 | M30: =VLOOKUP(I30,$AL$1:$AM$40,2,FALSE) -> 19.380345 | N30: =L30/M30 -> 0.17479494 | T30: 317 | U30: 2 | V30: 6 | W30: 0.65938196 | X30: Control | Y30: =AVERAGEIF($I$2:$I$577,T30,$E$2:$E$577) -> 626.2 | Z30: =AVERAGEIF($I$2:$I$577,T30,$K$2:$K$577) -> 819.264 | AA30: =AVERAGEIF($I$2:$I$577,T30,$L$2:$L$577) -> 3.3286897 | AB30: =AVERAGEIF($I$2:$I$577,T30,$M$2:$M$577) -> 19.655293 | AC30: =AVERAGEIF($I$2:$I$577,T30,$N$2:$N$577) -> 0.16935335 | AL30: 318 | AM30: 20.764817
A31: 4497 | B31: =VLOOKUP(A31,'[1]Nebris 11.27'!E:I,5,FALSE) -> 564 | C31: =VLOOKUP(A31,'[1]Nebris 11.28.23'!E:I,5,FALSE) -> 550 | D31: =B31-C31 -> 14 | E31: =AVERAGE(B31:C31) -> 557 | F31: 1 | G31: 3 | H31: 0.84590383 | I31: 214 | J31: =VLOOKUP(I31,$T$2:$X$57,5,FALSE) -> 25% MDGS Constant | K31: =VLOOKUP(A31,'[1]Interim '!E:I,5,FALSE)*0.96 -> 760.32 | L31: =(K31-E31)/58 -> 3.5055172 | M31: =VLOOKUP(I31,$AL$1:$AM$40,2,FALSE) -> 19.209834 | N31: =L31/M31 -> 0.18248555 | T31: 318 | U31: 2 | V31: 6 | W31: 0.88796535 | X31: 10% MDGS Variable | Y31: =AVERAGEIF($I$2:$I$577,T31,$E$2:$E$577) -> 628.5 | Z31: =AVERAGEIF($I$2:$I$577,T31,$K$2:$K$577) -> 811.584 | AA31: =AVERAGEIF($I$2:$I$577,T31,$L$2:$L$577) -> 3.1566207 | AB31: =AVERAGEIF($I$2:$I$577,T31,$M$2:$M$577) -> 20.764817 | AC31: =AVERAGEIF($I$2:$I$577,T31,$N$2:$N$577) -> 0.15201775 | AL31: 405 | AM31: 21.614662
A32: 4501 | B32: =VLOOKUP(A32,'[1]Nebris 11.27'!E:I,5,FALSE) -> 570 | C32: =VLOOKUP(A32,'[1]Nebris 11.28.23'!E:I,5,FALSE) -> 576 | D32: =B32-C32 -> -6 | E32: =AVERAGE(B32:C32) -> 573 | F32: 1 | G32: 4 | H32: 0.01228384 | I32: 205 | J32: =VLOOKUP(I32,$T$2:$X$57,5,FALSE) -> 10% MDGS Constant | K32: =VLOOKUP(A32,'[1]Interim '!E:I,5,FALSE)*0.96 -> 720 | L32: =(K32-E32)/58 -> 2.5344828 | M32: =VLOOKUP(I32,$AL$1:$AM$40,2,FALSE) -> 18.341718 | N32: =L32/M32 -> 0.13818132 | T32: 405 | U32: 3 | V32: 7 | W32: 0.0090366313 | X32: 10% MDGS Variable | Y32: =AVERAGEIF($I$2:$I$577,T32,$E$2:$E$577) -> 695.6 | Z32: =AVERAGEIF($I$2:$I$577,T32,$K$2:$K$577) -> 908.352 | AA32: =AVERAGEIF($I$2:$I$577,T32,$L$2:$L$577) -> 3.6681379 | AB32: =AVERAGEIF($I$2:$I$577,T32,$M$2:$M$577) -> 21.614662 | AC32: =AVERAGEIF($I$2:$I$577,T32,$N$2:$N$577) -> 0.169706 | AL32: 406 | AM32: 22.446449
A33: 4361 | B33: =VLOOKUP(A33,'[1]Nebris 11.27'!E:I,5,FALSE) -> 570 | C33: =VLOOKUP(A33,'[1]Nebris 11.28.23'!E:I,5,FALSE) -> 592 | D33: =B33-C33 -> -22 | E33: =AVERAGE(B33:C33) -> 581 | F33: 1 | G33: 4 | H33: 0.17528597 | I33: 206 | J33: =VLOOKUP(I33,$T$2:$X$57,5,FALSE) -> 10% MDGS Variable | K33: =VLOOKUP(A33,'[1]Interim '!E:I,5,FALSE)*0.96 -> 804.48 | L33: =(K33-E33)/58 -> 3.8531034 | M33: =VLOOKUP(I33,$AL$1:$AM$40,2,FALSE) -> 18.076576 | N33: =L33/M33 -> 0.2131545 | T33: 406 | U33: 3 | V33: 7 | W33: 0.51593629 | X33: 10% MDGS Constant | Y33: =AVERAGEIF($I$2:$I$577,T33,$E$2:$E$577) -> 702.7 | Z33: =AVERAGEIF($I$2:$I$577,T33,$K$2:$K$577) -> 924.096 | AA33: =AVERAGEIF($I$2:$I$577,T33,$L$2:$L$577) -> 3.8171724 | AB33: =AVERAGEIF($I$2:$I$577,T33,$M$2:$M$577) -> 22.446449 | AC33: =AVERAGEIF($I$2:$I$577,T33,$N$2:$N$577) -> 0.17005685 | AL33: 407 | AM33: 21.57522
A34: 4469 | B34: =VLOOKUP(A34,'[1]Nebris 11.27'!E:I,5,FALSE) -> 566 | C34: =VLOOKUP(A34,'[1]Nebris 11.28.23'!E:I,5,FALSE) -> 574 | D34: =B34-C34 -> -8 | E34: =AVERAGE(B34:C34) -> 570 | F34: 1 | G34: 4 | H34: 0.27520012 | I34: 207 | J34: =VLOOKUP(I34,$T$2:$X$57,5,FALSE) -> Control | K34: =VLOOKUP(A34,'[1]Interim '!E:I,5,FALSE)*0.96 -> 771.84 | L34: =(K34-E34)/58 -> 3.48 | M34: =VLOOKUP(I34,$AL$1:$AM$40,2,FALSE) -> 18.548331 | N34: =L34/M34 -> 0.18761796 | T34: 407 | U34: 3 | V34: 7 | W34: 0.82183375 | X34: 25% MDGS Variable | Y34: =AVERAGEIF($I$2:$I$577,T34,$E$2:$E$577) -> 699.8 | Z34: =AVERAGEIF($I$2:$I$577,T34,$K$2:$K$577) -> 871.68 | AA34: =AVERAGEIF($I$2:$I$577,T34,$L$2:$L$577) -> 2.9634483 | AB34: =AVERAGEIF($I$2:$I$577,T34,$M$2:$M$577) -> 21.57522 | AC34: =AVERAGEIF($I$2:$I$577,T34,$N$2:$N$577) -> 0.13735426 | AL34: 408 | AM34: 20.467026
A35: 4486 | B35: =VLOOKUP(A35,'[1]Nebris 11.27'!E:I,5,FALSE) -> 570 | C35: =VLOOKUP(A35,'[1]Nebris 11.28.23'!E:I,5,FALSE) -> 584 | D35: =B35-C35 -> -14 | E35: =AVERAGE(B35:C35) -> 577 | F35: 1 | G35: 4 | H35: 0.40382694 | I35: 208 | J35: =VLOOKUP(I35,$T$2:$X$57,5,FALSE) -> 25% MDGS Variable | K35: =VLOOKUP(A35,'[1]Interim '!E:I,5,FALSE)*0.96 -> 816 | L35: =(K35-E35)/58 -> 4.1206897 | M35: =VLOOKUP(I35,$AL$1:$AM$40,2,FALSE) -> 20.130157 | N35: =L35/M35 -> 0.20470231 | T35: 408 | U35: 3 | V35: 7 | W35: 0.93784093 | X35: Control | Y35: =AVERAGEIF($I$2:$I$577,T35,$E$2:$E$577) -> 697.6 | Z35: =AVERAGEIF($I$2:$I$577,T35,$K$2:$K$577) -> 872.256 | AA35: =AVERAGEIF($I$2:$I$577,T35,$L$2:$L$577) -> 3.0113103 | AB35: =AVERAGEIF($I$2:$I$577,T35,$M$2:$M$577) -> 20.467026 | AC35: =AVERAGEIF($I$2:$I$577,T35,$N$2:$N$577) -> 0.14712984 | AL35: 409 | AM35: 22.100418
A36: 4425 | B36: =VLOOKUP(A36,'[1]Nebris 11.27'!E:I,5,FALSE) -> 570 | C36: =VLOOKUP(A36,'[1]Nebris 11.28.23'!E:I,5,FALSE) -> 580 | D36: =B36-C36 -> -10 | E36: =AVERAGE(B36:C36) -> 575 | F36: 1 | G36: 4 | H36: 0.46401232 | I36: 209 | J36: =VLOOKUP(I36,$T$2:$X$57,5,FALSE) -> 25% MDGS Constant | K36: =VLOOKUP(A36,'[1]Interim '!E:I,5,FALSE)*0.96 -> 804.48 | L36: =(K36-E36)/58 -> 3.9565517 | M36: =VLOOKUP(I36,$AL$1:$AM$40,2,FALSE) -> 19.349137 | N36: =L36/M36 -> 0.20448208 | T36: 409 | U36: 3 | V36: 7 | W36: 0.96875852 | X36: 25% MDGS Constant | Y36: =AVERAGEIF($I$2:$I$577,T36,$E$2:$E$577) -> 692.9 | Z36: =AVERAGEIF($I$2:$I$577,T36,$K$2:$K$577) -> 910.464 | AA36: =AVERAGEIF($I$2:$I$577,T36,$L$2:$L$577) -> 3.7511034 | AB36: =AVERAGEIF($I$2:$I$577,T36,$M$2:$M$577) -> 22.100418 | AC36: =AVERAGEIF($I$2:$I$577,T36,$N$2:$N$577) -> 0.16972998 | AL36: 410 | AM36: 20.775881
A37: 4546 | B37: =VLOOKUP(A37,'[1]Nebris 11.27'!E:I,5,FALSE) -> 570 | C37: =VLOOKUP(A37,'[1]Nebris 11.28.23'!E:I,5,FALSE) -> 576 | D37: =B37-C37 -> -6 | E37: =AVERAGE(B37:C37) -> 573 | F37: 1 | G37: 4 | H37: 0.51250615 | I37: 210 | J37: =VLOOKUP(I37,$T$2:$X$57,5,FALSE) -> 10% MDGS Constant | K37: =VLOOKUP(A37,'[1]Interim '!E:I,5,FALSE)*0.96 -> 737.28 | L37: =(K37-E37)/58 -> 2.8324138 | M37: =VLOOKUP(I37,$AL$1:$AM$40,2,FALSE) -> 17.600604 | N37: =L37/M37 -> 0.16092708 | T37: 410 | U37: 3 | V37: 8 | W37: 0.024862516 | X37: 25% MDGS Variable | Y37: =AVERAGEIF($I$2:$I$577,T37,$E$2:$E$577) -> 699.8 | Z37: =AVERAGEIF($I$2:$I$577,T37,$K$2:$K$577) -> 877.248 | AA37: =AVERAGEIF($I$2:$I$577,T37,$L$2:$L$577) -> 3.0594483 | AB37: =AVERAGEIF($I$2:$I$577,T37,$M$2:$M$577) -> 20.775881 | AC37: =AVERAGEIF($I$2:$I$577,T37,$N$2:$N$577) -> 0.14725962 | AL37: 411 | AM37: 20.848576
A38: 4716 | B38: =VLOOKUP(A38,'[1]Nebris 11.27'!E:I,5,FALSE) -> 564 | C38: =VLOOKUP(A38,'[1]Nebris 11.28.23'!E:I,5,FALSE) -> 552 | D38: =B38-C38 -> 12 | E38: =AVERAGE(B38:C38) -> 558 | F38: 1 | G38: 4 | H38: 0.67462159 | I38: 211 | J38: =VLOOKUP(I38,$T$2:$X$57,5,FALSE) -> Control | K38: =VLOOKUP(A38,'[1]Interim '!E:I,5,FALSE)*0.96 -> 681.6 | L38: =(K38-E38)/58 -> 2.1310345 | M38: =VLOOKUP(I38,$AL$1:$AM$40,2,FALSE) -> 16.604744 | N38: =L38/M38 -> 0.1283389 | T38: 411 | U38: 3 | V38: 8 | W38: 0.075615844 | X38: 10% MDGS Constant | Y38: =AVERAGEIF($I$2:$I$577,T38,$E$2:$E$577) -> 700.11111 | Z38: =AVERAGEIF($I$2:$I$577,T38,$K$2:$K$577) -> 887.04 | AA38: =AVERAGEIF($I$2:$I$577,T38,$L$2:$L$577) -> 3.2229119 | AB38: =AVERAGEIF($I$2:$I$577,T38,$M$2:$M$577) -> 20.848576 | AC38: =AVERAGEIF($I$2:$I$577,T38,$N$2:$N$577) -> 0.15458667 | AL38: 412 | AM38: 20.855004
... A40: 4772 | B40: =VLOOKUP(A40,'[1]Nebris 11.27'!E:I,5,FALSE) -> 566 | C40: =VLOOKUP(A40,'[1]Nebris 11.28.23'!E:I,5,FALSE) -> 570 | D40: =B40-C40 -> -4 | E40: =AVERAGE(B40:C40) -> 568 | F40: 1 | G40: 4 | H40: 0.83502981 | I40: 213 | J40: =VLOOKUP(I40,$T$2:$X$57,5,FALSE) -> 10% MDGS Variable | K40: =VLOOKUP(A40,'[1]Interim '!E:I,5,FALSE)*0.96 -> 754.56 | L40: =(K40-E40)/58 -> 3.2165517 | M40: =VLOOKUP(I40,$AL$1:$AM$40,2,FALSE) -> 19.380345 | N40: =L40/M40 -> 0.16596978 | T40: 413 | U40: 3 | V40: 8 | W40: 0.43684469 | X40: 25% MDGS Constant | Y40: =AVERAGEIF($I$2:$I$577,T40,$E$2:$E$577) -> 700.4 | Z40: =AVERAGEIF($I$2:$I$577,T40,$K$2:$K$577) -> 941.952 | AA40: =AVERAGEIF($I$2:$I$577,T40,$L$2:$L$577) -> 4.1646897 | AB40: =AVERAGEIF($I$2:$I$577,T40,$M$2:$M$577) -> 22.388856 | AC40: =AVERAGEIF($I$2:$I$577,T40,$N$2:$N$577) -> 0.18601619 | AL40: 414 | AM40: 22.801713
A41: 4450 | B41: =VLOOKUP(A41,'[1]Nebris 11.27'!E:I,5,FALSE) -> 570 | C41: =VLOOKUP(A41,'[1]Nebris 11.28.23'!E:I,5,FALSE) -> 570 | D41: =B41-C41 -> 0 | E41: =AVERAGE(B41:C41) -> 570 | F41: 1 | G41: 4 | H41: 0.98729662 | I41: 214 | J41: =VLOOKUP(I41,$T$2:$X$57,5,FALSE) -> 25% MDGS Constant | K41: =VLOOKUP(A41,'[1]Interim '!E:I,5,FALSE)*0.96 -> 727.68 | L41: =(K41-E41)/58 -> 2.7186207 | M41: =VLOOKUP(I41,$AL$1:$AM$40,2,FALSE) -> 19.209834 | N41: =L41/M41 -> 0.14152234 | T41: 414 | U41: 3 | V41: 8 | W41: 0.9029848 | X41: 10% MDGS Variable | Y41: =AVERAGEIF($I$2:$I$577,T41,$E$2:$E$577) -> 695.2 | Z41: =AVERAGEIF($I$2:$I$577,T41,$K$2:$K$577) -> 900.096 | AA41: =AVERAGEIF($I$2:$I$577,T41,$L$2:$L$577) -> 3.5326897 | AB41: =AVERAGEIF($I$2:$I$577,T41,$M$2:$M$577) -> 22.801713 | AC41: =AVERAGEIF($I$2:$I$577,T41,$N$2:$N$577) -> 0.15493089
...

Sheet Final Performance
A1: Lnk_AnID | B1: Initial | C1: Block | D1: Pen | E1: Treatment | F1: HCW | G1: CAFBW | H1: ADG | I1: DMI | J1: Lb Gain | K1: G:F | L1: Liver Abscess | P1: Abscess Count | Q1: Contaminated Livers | R1: REA | S1: Yield Grade | T1: Fat | U1: Marbling | W1: Pen | X1: Block | Y1: Rep | Z1: TRT | AA1: Initial | AB1: HCW | AC1: CAFBW | AD1: ADG | AE1: DMI | AF1: G:F | AG1: F:G | AH1: Liver Abscess | AI1: REA | AJ1: Yield Grade | AK1: Fat | AL1: Marbling | AN1: Treatment | AO1: Initial | AP1: HCW | AQ1: CAFBW | AR1: ADG | AS1: DMO | AT1: G:F | AU1: Liver Abscess | AV1: REA | AW1: Yield Grade | AX1: Fat | AY1: Marbling
A2: 4437 | B2: =VLOOKUP(A2,[1]Assign!$A:$D,4,FALSE) -> 561 | C2: 1 | D2: 205 | E2: =VLOOKUP(A2,[1]Assign!$A:$I,9,FALSE) -> 10% MDGS Constant | F2: =VLOOKUP(A2,'[1]Carcass '!$C$105:$D$397,2,FALSE) -> 774 | G2: =F2/0.63 -> 1228.5714 | H2: =(G2-B2)/196 -> 3.4059767 | I2: =VLOOKUP(D2,'[1]DMO head'!$A$2:$D$49,4,FALSE) -> 21.582642 | J2: =G2-B2 -> 667.57143 | L2: =VLOOKUP(A2,'[1]Carcass '!$C$10:$J$397,8,FALSE) -> 0 | M2: =COUNTIF(L2,"A") -> 0 | N2: =COUNTIF(L2,"A-") -> 0 | O2: =COUNTIF(L2,"A+") -> 0 | P2: =SUM(M2:O2) -> 0 | Q2: =COUNTIF(L2,"C") -> 0 | R2: =VLOOKUP(A2,'[1]Carcass '!$C$107:$E$399,3,FALSE) -> 12.6 | S2: =VLOOKUP(A2,'[1]Carcass '!$C$107:$F$399,4,FALSE) -> 3.3 | T2: =VLOOKUP(A2,'[1]Carcass '!$C$10:$G$397,5, FALSE) -> 0.58 | U2: =VLOOKUP(A2,'[1]Carcass '!$C$107:$I$399,7,FALSE) -> 708 | W2: 205 | X2: 1 | Y2: 1 | Z2: 10% MDGS Constant | AA2: =AVERAGEIF(D:D,W2,B:B) -> 572.4 | AB2: =AVERAGEIF(D:D,W2,F:F) -> 776.9 | AC2: =AVERAGEIF(D:D,W2,G:G) -> 1233.1746 | AD2: =AVERAGEIF(D:D,W2,H:H) -> 3.371299 | AE2: =VLOOKUP(W2,'[1]DMO head'!$A$2:$D$49,4,FALSE) -> 21.582642 | AF2: =AD2/AE2 -> 0.15620418 | AG2: =AE2/AD2 -> 6.4018773 | AI2: =AVERAGEIF(D:D,W2,R:R) -> 13.422 | AJ2: =AVERAGEIF(D:D,W2,S:S) -> 3.097 | AK2: =AVERAGEIF(D:D,W2,T:T) -> 0.5228 | AL2: =AVERAGEIF(D:D,W2,U:U) -> 533.66667 | AN2: Control | AO2: =AVERAGEIF(Z:Z,AN2,AA:AA) -> 631.80556 | AP2: =AVERAGEIF(Z:Z,AN2,AB:AB) -> 821.27396 | AQ2: =AVERAGEIF(Z:Z,AN2,$AC$1:$AC$41) -> 1303.6095 | AR2: =AVERAGEIF(Z:Z,AN2,AD:AD) -> 3.4895653 | AS2: =AVERAGEIF(Z:Z,AN2,AE:AE) -> 22.134382 | AT2: =AVERAGEIF(Z:Z,AN2,AF:AF) -> 0.15788147 | AV2: =AVERAGEIF(Z:Z,AN2,AI:AI) -> 13.651955 | AW2: =AVERAGEIF(Z:Z,AN2,AJ:AJ) -> 3.3295104 | AX2: =AVERAGEIF(Z:Z,AN2,AK:AK) -> 0.62500278 | AY2: =AVERAGEIF(Z:Z,AN2,AL:AL) -> 535.17426
A3: 4315 | B3: =VLOOKUP(A3,[1]Assign!$A:$D,4,FALSE) -> 554 | C3: 1 | D3: 206 | E3: =VLOOKUP(A3,[1]Assign!$A:$I,9,FALSE) -> 10% MDGS Variable | F3: =VLOOKUP(A3,'[1]Carcass '!$C$105:$D$397,2,FALSE) -> 750 | G3: =F3/0.63 -> 1190.4762 | H3: =(G3-B3)/196 -> 3.2473275 | I3: =VLOOKUP(D3,'[1]DMO head'!$A$2:$D$49,4,FALSE) -> 20.595227 | J3: =G3-B3 -> 636.47619 | L3: =VLOOKUP(A3,'[1]Carcass '!$C$10:$J$397,8,FALSE) -> 0 | M3: =COUNTIF(L3,"A") -> 0 | N3: =COUNTIF(L3,"A-") -> 0 | O3: =COUNTIF(L3,"A+") -> 0 | P3: =SUM(M3:O3) -> 0 | Q3: =COUNTIF(L3,"C") -> 0 | R3: =VLOOKUP(A3,'[1]Carcass '!$C$107:$E$399,3,FALSE) -> 14.1 | S3: =VLOOKUP(A3,'[1]Carcass '!$C$107:$F$399,4,FALSE) -> 3.6 | T3: =VLOOKUP(A3,'[1]Carcass '!$C$10:$G$397,5, FALSE) -> 0.66 | U3: =VLOOKUP(A3,'[1]Carcass '!$C$107:$I$399,7,FALSE) -> 469 | W3: 206 | X3: 1 | Y3: 1 | Z3: 10% MDGS Variable | AA3: =AVERAGEIF(D:D,W3,B:B) -> 575.4 | AB3: =AVERAGEIF(D:D,W3,F:F) -> 772.1 | AC3: =AVERAGEIF(D:D,W3,G:G) -> 1232.1429 | AD3: =AVERAGEIF(D:D,W3,H:H) -> 3.359785 | AE3: =VLOOKUP(W3,'[1]DMO head'!$A$2:$D$49,4,FALSE) -> 20.595227 | AF3: =AD3/AE3 -> 0.16313416 | AG3: =AE3/AD3 -> 6.1299241 | AI3: =AVERAGEIF(D:D,W3,R:R) -> 14.018889 | AJ3: =AVERAGEIF(D:D,W3,S:S) -> 3.3288889 | AK3: =AVERAGEIF(D:D,W3,T:T) -> 0.57314286 | AL3: =AVERAGEIF(D:D,W3,U:U) -> 485 | AN3: 10% MDGS Constant | AO3: =AVERAGEIF(Z:Z,AN3,AA:AA) -> 632.45556 | AP3: =AVERAGEIF(Z:Z,AN3,AB:AB) -> 830.17778 | AQ3: =AVERAGEIF(Z:Z,AN3,$AC$1:$AC$41) -> 1318.534 | AR3: =AVERAGEIF(Z:Z,AN3,AD:AD) -> 3.5671272 | AS3: =AVERAGEIF(Z:Z,AN3,AE:AE) -> 22.339124 | AT3: =AVERAGEIF(Z:Z,AN3,AF:AF) -> 0.1598419 | AV3: =AVERAGEIF(Z:Z,AN3,AI:AI) -> 13.77976 | AW3: =AVERAGEIF(Z:Z,AN3,AJ:AJ) -> 3.3848854 | AX3: =AVERAGEIF(Z:Z,AN3,AK:AK) -> 0.62793413 | AY3: =AVERAGEIF(Z:Z,AN3,AL:AL) -> 560.95933
A4: 4322 | B4: =VLOOKUP(A4,[1]Assign!$A:$D,4,FALSE) -> 565 | C4: 1 | D4: 207 | E4: =VLOOKUP(A4,[1]Assign!$A:$I,9,FALSE) -> Control | F4: =VLOOKUP(A4,'[1]Carcass '!$C$105:$D$397,2,FALSE) -> 736 | G4: =F4/0.63 -> 1168.254 | H4: =(G4-B4)/196 -> 3.0778264 | I4: =VLOOKUP(D4,'[1]DMO head'!$A$2:$D$49,4,FALSE) -> 21.495747 | J4: =G4-B4 -> 603.25397 | L4: =VLOOKUP(A4,'[1]Carcass '!$C$10:$J$397,8,FALSE) -> A+ | M4: =COUNTIF(L4,"A") -> 0 | N4: =COUNTIF(L4,"A-") -> 0 | O4: =COUNTIF(L4,"A+") -> 1 | P4: =SUM(M4:O4) -> 1 | Q4: =COUNTIF(L4,"C") -> 0 | R4: =VLOOKUP(A4,'[1]Carcass '!$C$107:$E$399,3,FALSE) -> 13.4 | S4: =VLOOKUP(A4,'[1]Carcass '!$C$107:$F$399,4,FALSE) -> 3.25 | T4: =VLOOKUP(A4,'[1]Carcass '!$C$10:$G$397,5, FALSE) -> 0.524 | U4: =VLOOKUP(A4,'[1]Carcass '!$C$107:$I$399,7,FALSE) -> 550 | W4: 207 | X4: 1 | Y4: 1 | Z4: Control | AA4: =AVERAGEIF(D:D,W4,B:B) -> 579 | AB4: =AVERAGEIF(D:D,W4,F:F) -> 802.2 | AC4: =AVERAGEIF(D:D,W4,G:G) -> 1273.3333 | AD4: =AVERAGEIF(D:D,W4,H:H) -> 3.542517 | AE4: =VLOOKUP(W4,'[1]DMO head'!$A$2:$D$49,4,FALSE) -> 21.495747 | AF4: =AD4/AE4 -> 0.16480083 | AG4: =AE4/AD4 -> 6.0679306 | AI4: =AVERAGEIF(D:D,W4,R:R) -> 13.707 | AJ4: =AVERAGEIF(D:D,W4,S:S) -> 3.32 | AK4: =AVERAGEIF(D:D,W4,T:T) -> 0.60466667 | AL4: =AVERAGEIF(D:D,W4,U:U) -> 556.77778 | AN4: 10% MDGS Variable | AO4: =AVERAGEIF(Z:Z,AN4,AA:AA) -> 631.71389 | AP4: =AVERAGEIF(Z:Z,AN4,AB:AB) -> 833.5375 | AQ4: =AVERAGEIF(Z:Z,AN4,$AC$1:$AC$41) -> 1322.2994 | AR4: =AVERAGEIF(Z:Z,AN4,AD:AD) -> 3.5893564 | AS4: =AVERAGEIF(Z:Z,AN4,AE:AE) -> 22.695847 | AT4: =AVERAGEIF(Z:Z,AN4,AF:AF) -> 0.15841924 | AV4: =AVERAGEIF(Z:Z,AN4,AI:AI) -> 13.817294 | AW4: =AVERAGEIF(Z:Z,AN4,AJ:AJ) -> 3.4278943 | AX4: =AVERAGEIF(Z:Z,AN4,AK:AK) -> 0.66074911 | AY4: =AVERAGEIF(Z:Z,AN4,AL:AL) -> 571.6559
A5: 4765 | B5: =VLOOKUP(A5,[1]Assign!$A:$D,4,FALSE) -> 556 | C5: 1 | D5: 209 | E5: =VLOOKUP(A5,[1]Assign!$A:$I,9,FALSE) -> 25% MDGS Constant | F5: =VLOOKUP(A5,'[1]Carcass '!$C$105:$D$397,2,FALSE) -> 796 | G5: =F5/0.63 -> 1263.4921 | H5: =(G5-B5)/196 -> 3.6096534 | I5: =VLOOKUP(D5,'[1]DMO head'!$A$2:$D$49,4,FALSE) -> 21.321409 | J5: =G5-B5 -> 707.49206 | L5: =VLOOKUP(A5,'[1]Carcass '!$C$10:$J$397,8,FALSE) -> A+ | M5: =COUNTIF(L5,"A") -> 0 | N5: =COUNTIF(L5,"A-") -> 0 | O5: =COUNTIF(L5,"A+") -> 1 | P5: =SUM(M5:O5) -> 1 | Q5: =COUNTIF(L5,"C") -> 0 | R5: =VLOOKUP(A5,'[1]Carcass '!$C$107:$E$399,3,FALSE) -> 13.4 | S5: =VLOOKUP(A5,'[1]Carcass '!$C$107:$F$399,4,FALSE) -> 4.1 | T5: =VLOOKUP(A5,'[1]Carcass '!$C$10:$G$397,5, FALSE) -> 1 | U5: =VLOOKUP(A5,'[1]Carcass '!$C$107:$I$399,7,FALSE) -> 531 | W5: 208 | X5: 1 | Y5: 1 | Z5: 25% MDGS Variable | AA5: =AVERAGEIF(D:D,W5,B:B) -> 580.5 | AB5: =AVERAGEIF(D:D,W5,F:F) -> 816.5 | AC5: =AVERAGEIF(D:D,W5,G:G) -> 1296.0317 | AD5: =AVERAGEIF(D:D,W5,H:H) -> 3.6506722 | AE5: =VLOOKUP(W5,'[1]DMO head'!$A$2:$D$49,4,FALSE) -> 22.923741 | AF5: =AD5/AE5 -> 0.1592529 | AG5: =AE5/AD5 -> 6.2793205 | AI5: =AVERAGEIF(D:D,W5,R:R) -> 14.25 | AJ5: =AVERAGEIF(D:D,W5,S:S) -> 3.35375 | AK5: =AVERAGEIF(D:D,W5,T:T) -> 0.63625 | AL5: =AVERAGEIF(D:D,W5,U:U) -> 547.875 | AN5: 25% MDGS Constant | AO5: =AVERAGEIF(Z:Z,AN5,AA:AA) -> 630.28472 | AP5: =AVERAGEIF(Z:Z,AN5,AB:AB) -> 852.02639 | AQ5: =AVERAGEIF(Z:Z,AN5,$AC$1:$AC$41) -> 1353.8668 | AR5: =AVERAGEIF(Z:Z,AN5,AD:AD) -> 3.7603935 | AS5: =AVERAGEIF(Z:Z,AN5,AE:AE) -> 23.239689 | AT5: =AVERAGEIF(Z:Z,AN5,AF:AF) -> 0.16180511 | AV5: =AVERAGEIF(Z:Z,AN5,AI:AI) -> 13.921049 | AW5: =AVERAGEIF(Z:Z,AN5,AJ:AJ) -> 3.5698437 | AX5: =AVERAGEIF(Z:Z,AN5,AK:AK) -> 0.70233264 | AY5: =AVERAGEIF(Z:Z,AN5,AL:AL) -> 553.86791
A6: 4744 | B6: =VLOOKUP(A6,[1]Assign!$A:$D,4,FALSE) -> 554 | C6: 1 | D6: 210 | E6: =VLOOKUP(A6,[1]Assign!$A:$I,9,FALSE) -> 10% MDGS Constant | F6: =VLOOKUP(A6,'[1]Carcass '!$C$105:$D$397,2,FALSE) -> 876 | G6: =F6/0.63 -> 1390.4762 | H6: =(G6-B6)/196 -> 4.2677357 | I6: =VLOOKUP(D6,'[1]DMO head'!$A$2:$D$49,4,FALSE) -> 19.910352 | J6: =G6-B6 -> 836.47619 | L6: =VLOOKUP(A6,'[1]Carcass '!$C$10:$J$397,8,FALSE) -> C | M6: =COUNTIF(L6,"A") -> 0 | N6: =COUNTIF(L6,"A-") -> 0 | O6: =COUNTIF(L6,"A+") -> 0 | P6: =SUM(M6:O6) -> 0 | Q6: =COUNTIF(L6,"C") -> 1 | R6: =VLOOKUP(A6,'[1]Carcass '!$C$107:$E$399,3,FALSE) -> 17.7 | S6: =VLOOKUP(A6,'[1]Carcass '!$C$107:$F$399,4,FALSE) -> 3.3 | T6: =VLOOKUP(A6,'[1]Carcass '!$C$10:$G$397,5, FALSE) -> 0.63 | U6: =VLOOKUP(A6,'[1]Carcass '!$C$107:$I$399,7,FALSE) -> 367 | W6: 209 | X6: 1 | Y6: 1 | Z6: 25% MDGS Constant | AA6: =AVERAGEIF(D:D,W6,B:B) -> 573.55556 | AB6: =AVERAGEIF(D:D,W6,F:F) -> 770.33333 | AC6: =AVERAGEIF(D:D,W6,G:G) -> 1222.7513 | AD6: =AVERAGEIF(D:D,W6,H:H) -> 3.3122233 | AE6: =VLOOKUP(W6,'[1]DMO head'!$A$2:$D$49,4,FALSE) -> 21.321409 | AF6: =AD6/AE6 -> 0.1553473 | AG6: =AE6/AD6 -> 6.4371895 | AI6: =AVERAGEIF(D:D,W6,R:R) -> 13.434444 | AJ6: =AVERAGEIF(D:D,W6,S:S) -> 3.4633333 | AK6: =AVERAGEIF(D:D,W6,T:T) -> 0.672 | AL6: =AVERAGEIF(D:D,W6,U:U) -> 486.55556 | AN6: 25% MDGS Variable | AO6: =AVERAGEIF(Z:Z,AN6,AA:AA) -> 633.42813 | AP6: =AVERAGEIF(Z:Z,AN6,AB:AB) -> 840.44375 | AQ6: =AVERAGEIF(Z:Z,AN6,$AC$1:$AC$41) -> 1336.2798 | AR6: =AVERAGEIF(Z:Z,AN6,AD:AD) -> 3.6512056 | AS6: =AVERAGEIF(Z:Z,AN6,AE:AE) -> 22.67949 | AT6: =AVERAGEIF(Z:Z,AN6,AF:AF) -> 0.16101845 | AV6: =AVERAGEIF(Z:Z,AN6,AI:AI) -> 13.781295 | AW6: =AVERAGEIF(Z:Z,AN6,AJ:AJ) -> 3.4426007 | AX6: =AVERAGEIF(Z:Z,AN6,AK:AK) -> 0.6610249 | AY6: =AVERAGEIF(Z:Z,AN6,AL:AL) -> 546.23993
A7: 4773 | B7: =VLOOKUP(A7,[1]Assign!$A:$D,4,FALSE) -> 566 | C7: 1 | D7: 211 | E7: =VLOOKUP(A7,[1]Assign!$A:$I,9,FALSE) -> Control | F7: =VLOOKUP(A7,'[1]Carcass '!$C$105:$D$397,2,FALSE) -> 725 | G7: =F7/0.63 -> 1150.7937 | H7: =(G7-B7)/196 -> 2.9836411 | I7: =VLOOKUP(D7,'[1]DMO head'!$A$2:$D$49,4,FALSE) -> 19.728558 | J7: =G7-B7 -> 584.79365 | L7: =VLOOKUP(A7,'[1]Carcass '!$C$10:$J$397,8,FALSE) -> 0 | M7: =COUNTIF(L7,"A") -> 0 | N7: =COUNTIF(L7,"A-") -> 0 | O7: =COUNTIF(L7,"A+") -> 0 | P7: =SUM(M7:O7) -> 0 | Q7: =COUNTIF(L7,"C") -> 0 | R7: =VLOOKUP(A7,'[1]Carcass '!$C$107:$E$399,3,FALSE) -> 13.2 | S7: =VLOOKUP(A7,'[1]Carcass '!$C$107:$F$399,4,FALSE) -> 3.2 | T7: =VLOOKUP(A7,'[1]Carcass '!$C$10:$G$397,5, FALSE) -> 0.63 | U7: =VLOOKUP(A7,'[1]Carcass '!$C$107:$I$399,7,FALSE) -> 436 | W7: 210 | X7: 1 | Y7: 2 | Z7: 10% MDGS Constant | AA7: =AVERAGEIF(D:D,W7,B:B) -> 574.83333 | AB7: =AVERAGEIF(D:D,W7,F:F) -> 773.22222 | AC7: =AVERAGEIF(D:D,W7,G:G) -> 1227.3369 | AD7: =AVERAGEIF(D:D,W7,H:H) -> 3.3290996 | AE7: =VLOOKUP(W7,'[1]DMO head'!$A$2:$D$49,4,FALSE) -> 19.910352 | AF7: =AD7/AE7 -> 0.16720446 | AG7: =AE7/AD7 -> 5.9807017 | AI7: =AVERAGEIF(D:D,W7,R:R) -> 14.002222 | AJ7: =AVERAGEIF(D:D,W7,S:S) -> 3.3622222 | AK7: =AVERAGEIF(D:D,W7,T:T) -> 0.64133333 | AL7: =AVERAGEIF(D:D,W7,U:U) -> 521
A8: 4739 | B8: =VLOOKUP(A8,[1]Assign!$A:$D,4,FALSE) -> 555 | C8: 1 | D8: 212 | E8: =VLOOKUP(A8,[1]Assign!$A:$I,9,FALSE) -> 25% MDGS Variable | F8: =VLOOKUP(A8,'[1]Carcass '!$C$105:$D$397,2,FALSE) -> 757 | G8: =F8/0.63 -> 1201.5873 | H8: =(G8-B8)/196 -> 3.2989148 | I8: =VLOOKUP(D8,'[1]DMO head'!$A$2:$D$49,4,FALSE) -> 21.738936 | J8: =G8-B8 -> 646.5873 | L8: =VLOOKUP(A8,'[1]Carcass '!$C$10:$J$397,8,FALSE) -> 0 | M8: =COUNTIF(L8,"A") -> 0 | N8: =COUNTIF(L8,"A-") -> 0 | O8: =COUNTIF(L8,"A+") -> 0 | P8: =SUM(M8:O8) -> 0 | Q8: =COUNTIF(L8,"C") -> 0 | R8: =VLOOKUP(A8,'[1]Carcass '!$C$107:$E$399,3,FALSE) -> 12.9 | S8: =VLOOKUP(A8,'[1]Carcass '!$C$107:$F$399,4,FALSE) -> 3.3 | T8: =VLOOKUP(A8,'[1]Carcass '!$C$10:$G$397,5, FALSE) -> 0.604 | U8: =VLOOKUP(A8,'[1]Carcass '!$C$107:$I$399,7,FALSE) -> 551 | W8: 211 | X8: 1 | Y8: 2 | Z8: Control | AA8: =AVERAGEIF(D:D,W8,B:B) -> 575.4 | AB8: =AVERAGEIF(D:D,W8,F:F) -> 752.5 | AC8: =AVERAGEIF(D:D,W8,G:G) -> 1194.4444 | AD8: =AVERAGEIF(D:D,W8,H:H) -> 3.15839 | AE8: =VLOOKUP(W8,'[1]DMO head'!$A$2:$D$49,4,FALSE) -> 19.728558 | AF8: =AD8/AE8 -> 0.16009229 | AG8: =AE8/AD8 -> 6.2463969 | AI8: =AVERAGEIF(D:D,W8,R:R) -> 13.775 | AJ8: =AVERAGEIF(D:D,W8,S:S) -> 3.07 | AK8: =AVERAGEIF(D:D,W8,T:T) -> 0.4882 | AL8: =AVERAGEIF(D:D,W8,U:U) -> 515.6
A9: 4485 | B9: =VLOOKUP(A9,[1]Assign!$A:$D,4,FALSE) -> 557 | C9: 1 | D9: 213 | E9: =VLOOKUP(A9,[1]Assign!$A:$I,9,FALSE) -> 10% MDGS Variable | F9: =VLOOKUP(A9,'[1]Carcass '!$C$105:$D$397,2,FALSE) -> 916 | G9: =F9/0.63 -> 1453.9683 | H9: =(G9-B9)/196 -> 4.5763686 | I9: =VLOOKUP(D9,'[1]DMO head'!$A$2:$D$49,4,FALSE) -> 22.955779 | J9: =G9-B9 -> 896.96825 | L9: =VLOOKUP(A9,'[1]Carcass '!$C$10:$J$397,8,FALSE) -> 0 | M9: =COUNTIF(L9,"A") -> 0 | N9: =COUNTIF(L9,"A-") -> 0 | O9: =COUNTIF(L9,"A+") -> 0 | P9: =SUM(M9:O9) -> 0 | Q9: =COUNTIF(L9,"C") -> 0 | R9: =VLOOKUP(A9,'[1]Carcass '!$C$107:$E$399,3,FALSE) -> 14.4 | S9: =VLOOKUP(A9,'[1]Carcass '!$C$107:$F$399,4,FALSE) -> 3.5 | T9: =VLOOKUP(A9,'[1]Carcass '!$C$10:$G$397,5, FALSE) -> 0.71 | U9: =VLOOKUP(A9,'[1]Carcass '!$C$107:$I$399,7,FALSE) -> 722 | W9: 212 | X9: 1 | Y9: 2 | Z9: 25% MDGS Variable | AA9: =AVERAGEIF(D:D,W9,B:B) -> 575.6 | AB9: =AVERAGEIF(D:D,W9,F:F) -> 798.5 | AC9: =AVERAGEIF(D:D,W9,G:G) -> 1267.4603 | AD9: =AVERAGEIF(D:D,W9,H:H) -> 3.5298996 | AE9: =VLOOKUP(W9,'[1]DMO head'!$A$2:$D$49,4,FALSE) -> 21.738936 | AF9: =AD9/AE9 -> 0.16237684 | AG9: =AE9/AD9 -> 6.1585139 | AI9: =AVERAGEIF(D:D,W9,R:R) -> 13.28 | AJ9: =AVERAGEIF(D:D,W9,S:S) -> 3.328 | AK9: =AVERAGEIF(D:D,W9,T:T) -> 0.577 | AL9: =AVERAGEIF(D:D,W9,U:U) -> 526
A10: 4603 | B10: =VLOOKUP(A10,[1]Assign!$A:$D,4,FALSE) -> 562 | C10: 1 | D10: 214 | E10: =VLOOKUP(A10,[1]Assign!$A:$I,9,FALSE) -> 25% MDGS Constant | F10: =VLOOKUP(A10,'[1]Carcass '!$C$105:$D$397,2,FALSE) -> 866 | G10: =F10/0.63 -> 1374.6032 | H10: =(G10-B10)/196 -> 4.1459346 | I10: =VLOOKUP(D10,'[1]DMO head'!$A$2:$D$49,4,FALSE) -> 22.398785 | J10: =G10-B10 -> 812.60317 | L10: =VLOOKUP(A10,'[1]Carcass '!$C$10:$J$397,8,FALSE) -> C | M10: =COUNTIF(L10,"A") -> 0 | N10: =COUNTIF(L10,"A-") -> 0 | O10: =COUNTIF(L10,"A+") -> 0 | P10: =SUM(M10:O10) -> 0 | Q10: =COUNTIF(L10,"C") -> 1 | R10: =VLOOKUP(A10,'[1]Carcass '!$C$107:$E$399,3,FALSE) -> 14.5 | S10: =VLOOKUP(A10,'[1]Carcass '!$C$107:$F$399,4,FALSE) -> 3.5 | T10: =VLOOKUP(A10,'[1]Carcass '!$C$10:$G$397,5, FALSE) -> 0.71 | U10: =VLOOKUP(A10,'[1]Carcass '!$C$107:$I$399,7,FALSE) -> 411 | W10: 213 | X10: 1 | Y10: 2 | Z10: 10% MDGS Variable | AA10: =AVERAGEIF(D:D,W10,B:B) -> 571.9 | AB10: =AVERAGEIF(D:D,W10,F:F) -> 851.9 | AC10: =AVERAGEIF(D:D,W10,G:G) -> 1360.8466 | AD10: =AVERAGEIF(D:D,W10,H:H) -> 4.037199 | AE10: =VLOOKUP(W10,'[1]DMO head'!$A$2:$D$49,4,FALSE) -> 22.955779 | AF10: =AD10/AE10 -> 0.17586852 | AG10: =AE10/AD10 -> 5.6860658 | AI10: =AVERAGEIF(D:D,W10,R:R) -> 14.095556 | AJ10: =AVERAGEIF(D:D,W10,S:S) -> 3.5933333 | AK10: =AVERAGEIF(D:D,W10,T:T) -> 0.726 | AL10: =AVERAGEIF(D:D,W10,U:U) -> 643.11111
A11: 4683 | B11: =VLOOKUP(A11,[1]Assign!$A:$D,4,FALSE) -> 554 | C11: 1 | D11: 205 | E11: =VLOOKUP(A11,[1]Assign!$A:$I,9,FALSE) -> 10% MDGS Constant | F11: =VLOOKUP(A11,'[1]Carcass '!$C$105:$D$397,2,FALSE) -> 760 | G11: =F11/0.63 -> 1206.3492 | H11: =(G11-B11)/196 -> 3.3283123 | I11: =VLOOKUP(D11,'[1]DMO head'!$A$2:$D$49,4,FALSE) -> 21.582642 | J11: =G11-B11 -> 652.34921 | L11: =VLOOKUP(A11,'[1]Carcass '!$C$10:$J$397,8,FALSE) -> 0 | M11: =COUNTIF(L11,"A") -> 0 | N11: =COUNTIF(L11,"A-") -> 0 | O11: =COUNTIF(L11,"A+") -> 0 | P11: =SUM(M11:O11) -> 0 | Q11: =COUNTIF(L11,"C") -> 0 | R11: =VLOOKUP(A11,'[1]Carcass '!$C$107:$E$399,3,FALSE) -> 15.22 | S11: =VLOOKUP(A11,'[1]Carcass '!$C$107:$F$399,4,FALSE) -> 2.6 | T11: =VLOOKUP(A11,'[1]Carcass '!$C$10:$G$397,5, FALSE) -> 0.36 | U11: =VLOOKUP(A11,'[1]Carcass '!$C$107:$I$399,7,FALSE) -> 362 | W11: 214 | X11: 1 | Y11: 2 | Z11: 25% MDGS Constant | AA11: =AVERAGEIF(D:D,W11,B:B) -> 574 | AB11: =AVERAGEIF(D:D,W11,F:F) -> 826.1 | AC11: =AVERAGEIF(D:D,W11,G:G) -> 1311.2698 | AD11: =AVERAGEIF(D:D,W11,H:H) -> 3.7615808 | AE11: =VLOOKUP(W11,'[1]DMO head'!$A$2:$D$49,4,FALSE) -> 22.398785 | AF11: =AD11/AE11 -> 0.16793683 | AG11: =AE11/AD11 -> 5.9546201 | AI11: =AVERAGEIF(D:D,W11,R:R) -> 13.51 | AJ11: =AVERAGEIF(D:D,W11,S:S) -> 3.467 | AK11: =AVERAGEIF(D:D,W11,T:T) -> 0.67275 | AL11: =AVERAGEIF(D:D,W11,U:U) -> 539.875
A12: 4313 | B12: =VLOOKUP(A12,[1]Assign!$A:$D,4,FALSE) -> 560 | C12: 1 | D12: 206 | E12: =VLOOKUP(A12,[1]Assign!$A:$I,9,FALSE) -> 10% MDGS Variable | F12: =VLOOKUP(A12,'[1]Carcass '!$C$105:$D$397,2,FALSE) -> 782 | G12: =F12/0.63 -> 1241.2698 | H12: =(G12-B12)/196 -> 3.4758665 | I12: =VLOOKUP(D12,'[1]DMO head'!$A$2:$D$49,4,FALSE) -> 20.595227 | J12: =G12-B12 -> 681.26984 | L12: =VLOOKUP(A12,'[1]Carcass '!$C$10:$J$397,8,FALSE) -> A+ | M12: =COUNTIF(L12,"A") -> 0 | N12: =COUNTIF(L12,"A-") -> 0 | O12: =COUNTIF(L12,"A+") -> 1 | P12: =SUM(M12:O12) -> 1 | Q12: =COUNTIF(L12,"C") -> 0 | R12: =VLOOKUP(A12,'[1]Carcass '!$C$107:$E$399,3,FALSE) -> 13.7 | S12: =VLOOKUP(A12,'[1]Carcass '!$C$107:$F$399,4,FALSE) -> 2.8 | T12: =VLOOKUP(A12,'[1]Carcass '!$C$10:$G$397,5, FALSE) -> 0.37 | U12: =VLOOKUP(A12,'[1]Carcass '!$C$107:$I$399,7,FALSE) -> 389 | W12: 215 | X12: 2 | Y12: 3 | Z12: 10% MDGS Variable | AA12: =AVERAGEIF(D:D,W12,B:B) -> 629.55556 | AB12: =AVERAGEIF(D:D,W12,F:F) -> 834.11111 | AC12: =AVERAGEIF(D:D,W12,G:G) -> 1323.9859 | AD12: =AVERAGEIF(D:D,W12,H:H) -> 3.5430119 | AE12: =VLOOKUP(W12,'[1]DMO head'!$A$2:$D$49,4,FALSE) -> 21.579785 | AF12: =AD12/AE12 -> 0.16418198 | AG12: =AE12/AD12 -> 6.0908023 | AI12: =AVERAGEIF(D:D,W12,R:R) -> 14.248571 | AJ12: =AVERAGEIF(D:D,W12,S:S) -> 3.2585714 | AK12: =AVERAGEIF(D:D,W12,T:T) -> 0.674 | AL12: =AVERAGEIF(D:D,W12,U:U) -> 548.83333
A13: 4418 | B13: =VLOOKUP(A13,[1]Assign!$A:$D,4,FALSE) -> 572 | C13: 1 | D13: 207 | E13: =VLOOKUP(A13,[1]Assign!$A:$I,9,FALSE) -> Control | F13: =VLOOKUP(A13,'[1]Carcass '!$C$105:$D$397,2,FALSE) -> 789 | G13: =F13/0.63 -> 1252.381 | H13: =(G13-B13)/196 -> 3.4713314 | I13: =VLOOKUP(D13,'[1]DMO head'!$A$2:$D$49,4,FALSE) -> 21.495747 | J13: =G13-B13 -> 680.38095 | L13: =VLOOKUP(A13,'[1]Carcass '!$C$10:$J$397,8,FALSE) -> C | M13: =COUNTIF(L13,"A") -> 0 | N13: =COUNTIF(L13,"A-") -> 0 | O13: =COUNTIF(L13,"A+") -> 0 | P13: =SUM(M13:O13) -> 0 | Q13: =COUNTIF(L13,"C") -> 1 | R13: =VLOOKUP(A13,'[1]Carcass '!$C$107:$E$399,3,FALSE) -> 13.6 | S13: =VLOOKUP(A13,'[1]Carcass '!$C$107:$F$399,4,FALSE) -> 3.7 | T13: =VLOOKUP(A13,'[1]Carcass '!$C$10:$G$397,5, FALSE) -> 0.716 | U13: =VLOOKUP(A13,'[1]Carcass '!$C$107:$I$399,7,FALSE) -> 589 | W13: 216 | X13: 2 | Y13: 3 | Z13: 10% MDGS Constant | AA13: =AVERAGEIF(D:D,W13,B:B) -> 625.1 | AB13: =AVERAGEIF(D:D,W13,F:F) -> 803.8 | AC13: =AVERAGEIF(D:D,W13,G:G) -> 1275.873 | AD13: =AVERAGEIF(D:D,W13,H:H) -> 3.3202705 | AE13: =VLOOKUP(W13,'[1]DMO head'!$A$2:$D$49,4,FALSE) -> 21.830062 | AF13: =AD13/AE13 -> 0.15209624 | AG13: =AE13/AD13 -> 6.5747843 | AI13: =AVERAGEIF(D:D,W13,R:R) -> 13.67 | AJ13: =AVERAGEIF(D:D,W13,S:S) -> 3.425 | AK13: =AVERAGEIF(D:D,W13,T:T) -> 0.6254 | AL13: =AVERAGEIF(D:D,W13,U:U) -> 549.9
